Workbook

Sheet Резервации 2026
A1: Агент | B1: Дни слаб | C1: Дни среден | D1: Дни силен | E1: Номер | F1: Референтен номер | G1: Пристигане | H1: Date | I1: Month | J1: Заминаване | K1: Date | L1: Month | M1: Престой | N1: ABS | O1: Дни стартиращ месец | P1: Дни прикл месец | Q1: Компания | R1: Тип стая на пристигане | S1: Възрастни | T1: Деца | U1: Начисления за стая | V1: ADR | W1: Държава | X1: Създадена на | Y1: Референтна дата | Z1: Месец на резервацията | AA1: May | AB1: Jun | AC1: Jul | AD1: Aug | AE1: Sep | AF1: Total | AG1: Check | AH1: Date Res | AI1: WeekNumber | AJ1: StartDate | AK1: WeekStay | AL1: Анулирана | AM1: Начисления за стая без ДДС | AN1: ADR без ДДС
A2: =VLOOKUP(Q2,'Data validation'!$K$2:$L$50,2,FALSE) -> INDIVIDUAL | B2: =AA2+IF(I2="Jun",IF(_xlfn.NUMBERVALUE(H2)>14,0,IF(_xlfn.NUMBERVALUE(K2)<14,M2,15-_xlfn.NUMBERVALUE(H2))),0) -> 0 | C2: =M2-B2-D2 -> 0 | D2: =IF(L2="Jul",IF(_xlfn.NUMBERVALUE(K2)<11,0,IF(I2="Jul",IF(_xlfn.NUMBERVALUE(H2)>11,M2,_xlfn.NUMBERVALUE(K2)-11),0)),0)+IF(L2="Aug",IF(_xlfn.NUMBERVALUE(K2)>24,IF(_xlfn.NUMBERVALUE(H2)>24,0,25-_xlfn.NUMBERVALUE(H2)),IF(I2="Aug",M2,_xlfn.NUMBERVALUE(K2)-1+32-_xlfn.NUMBERVALUE(H2))),0) -> 5 | E2: 9775 | F2: 12122025 | G2: 18 Aug 2026 | H2: =LEFT(G2,2) -> 18 | I2: =MID(G2,4,3) -> Aug | J2: 23 Aug 2026 | K2: =LEFT(J2,2) -> 23 | L2: =MID(J2,4,3) -> Aug | M2: 5 | N2: =+K2-H2 -> 5 | O2: =IF(I2=L2,0,31-H2) -> 0 | P2: =IF(I2=L2,0,K2-1) -> 0 | Q2: INDIVIDUAL | R2: APP1-SEA | S2: 2 | T2: 3 | U2: 2637.679 | V2: 527.5358 | X2: 27 Jan 2026 13:20 | Y2: 27 Jan 2026 | Z2: =MID(X2,4,3) -> Jan | AA2: =IF($I2=AA$1,IF($L2=AA$1,$M2,$O2),IF($L2=AA$1,$P2,0)) -> 0 | AB2: =IF($I2=AB$1,IF($L2=AB$1,$M2,$O2),IF($L2=AB$1,$P2,0)) -> 0 | AC2: =IF($I2=AC$1,IF($L2=AC$1,$M2,$O2),IF($L2=AC$1,$P2,0)) -> 0 | AD2: =IF($I2=AD$1,IF($L2=AD$1,$M2,$O2),IF($L2=AD$1,$P2,0)) -> 5 | AE2: =IF($I2=AE$1,IF($L2=AE$1,$M2,$O2),IF($L2=AE$1,$P2,0)) -> 0 | AF2: =SUM(AA2:AE2) -> 5 | AG2: =+AF2-M2 -> 0 | AH2: =LEFT(X2,2)&"."&VLOOKUP(MID(X2,4,3),'Data validation'!$A$1:$B$12,2,FALSE)&".2025" -> 27.01.2025 | AI2: =WEEKNUM(AH2) -> 5 | AJ2: =H2&"."&VLOOKUP(I2,'Data validation'!$A$1:$B$12,2,FALSE)&".2026" -> 18.08.2026 | AK2: =WEEKNUM(AJ2) -> 34 | AL2: =VLOOKUP(E2,[2]Sheet1!$A:$B,2,FALSE) -> #N/A
A3: =VLOOKUP(Q3,'Data validation'!$K$2:$L$50,2,FALSE) -> BOOKING | B3: =AA3+IF(I3="Jun",IF(_xlfn.NUMBERVALUE(H3)>14,0,IF(_xlfn.NUMBERVALUE(K3)<14,M3,15-_xlfn.NUMBERVALUE(H3))),0) -> 2 | C3: =M3-B3-D3 -> 1 | D3: =IF(L3="Jul",IF(_xlfn.NUMBERVALUE(K3)<11,0,IF(I3="Jul",IF(_xlfn.NUMBERVALUE(H3)>11,M3,_xlfn.NUMBERVALUE(K3)-11),0)),0)+IF(L3="Aug",IF(_xlfn.NUMBERVALUE(K3)>24,IF(_xlfn.NUMBERVALUE(H3)>24,0,25-_xlfn.NUMBERVALUE(H3)),IF(I3="Aug",M3,_xlfn.NUMBERVALUE(K3)-1+32-_xlfn.NUMBERVALUE(H3))),0) -> 0 | E3: 9413 | F3: 6652855982 | G3: 29 May 2026 | H3: =LEFT(G3,2) -> 29 | I3: =MID(G3,4,3) -> May | J3: 01 Jun 2026 | K3: =LEFT(J3,2) -> 01 | L3: =MID(J3,4,3) -> Jun | M3: 3 | N3: =+K3-H3 -> -28 | O3: =IF(I3=L3,0,31-H3) -> 2 | P3: =IF(I3=L3,0,K3-1) -> 0 | Q3: BOOKING | R3: APP2-POOL | S3: 2 | T3: 3 | U3: 1264.471 | V3: 421.49034 | W3: Romania | X3: 09 Jan 2026 18:54 | Y3: 09 Jan 2026 | Z3: =MID(X3,4,3) -> Jan | AA3: =IF($I3=AA$1,IF($L3=AA$1,$M3,$O3),IF($L3=AA$1,$P3,0)) -> 2 | AB3: =IF($I3=AB$1,IF($L3=AB$1,$M3,$O3),IF($L3=AB$1,$P3,0)) -> 0 | AC3: =IF($I3=AC$1,IF($L3=AC$1,$M3,$O3),IF($L3=AC$1,$P3,0)) -> 0 | AD3: =IF($I3=AD$1,IF($L3=AD$1,$M3,$O3),IF($L3=AD$1,$P3,0)) -> 0 | AE3: =IF($I3=AE$1,IF($L3=AE$1,$M3,$O3),IF($L3=AE$1,$P3,0)) -> 0 | AF3: =SUM(AA3:AE3) -> 2 | AG3: =+AF3-M3 -> -1 | AH3: =LEFT(X3,2)&"."&VLOOKUP(MID(X3,4,3),'Data validation'!$A$1:$B$12,2,FALSE)&".2025" -> 09.01.2025 | AI3: =WEEKNUM(AH3) -> 2 | AJ3: =H3&"."&VLOOKUP(I3,'Data validation'!$A$1:$B$12,2,FALSE)&".2026" -> 29.05.2026 | AK3: =WEEKNUM(AJ3) -> 22 | AL3: =VLOOKUP(E3,[2]Sheet1!$A:$B,2,FALSE) -> #N/A
A4: =VLOOKUP(Q4,'Data validation'!$K$2:$L$50,2,FALSE) -> TO | B4: =AA4+IF(I4="Jun",IF(_xlfn.NUMBERVALUE(H4)>14,0,IF(_xlfn.NUMBERVALUE(K4)<14,M4,15-_xlfn.NUMBERVALUE(H4))),0) -> 0 | C4: =M4-B4-D4 -> 7 | D4: =IF(L4="Jul",IF(_xlfn.NUMBERVALUE(K4)<11,0,IF(I4="Jul",IF(_xlfn.NUMBERVALUE(H4)>11,M4,_xlfn.NUMBERVALUE(K4)-11),0)),0)+IF(L4="Aug",IF(_xlfn.NUMBERVALUE(K4)>24,IF(_xlfn.NUMBERVALUE(H4)>24,0,25-_xlfn.NUMBERVALUE(H4)),IF(I4="Aug",M4,_xlfn.NUMBERVALUE(K4)-1+32-_xlfn.NUMBERVALUE(H4))),0) -> 0 | E4: 9620 | F4: 3896 | G4: 23 Jun 2026 | H4: =LEFT(G4,2) -> 23 | I4: =MID(G4,4,3) -> Jun | J4: 30 Jun 2026 | K4: =LEFT(J4,2) -> 30 | L4: =MID(J4,4,3) -> Jun | M4: 7 | N4: =+K4-H4 -> 7 | O4: =IF(I4=L4,0,31-H4) -> 0 | P4: =IF(I4=L4,0,K4-1) -> 0 | Q4: ТЕДИ - КАМ - ЕООД | R4: ROOM-DELUXE | S4: 2 | T4: 2 | U4: =SUMIFS(TediKam!L:L,TediKam!D:D,'Резервации 2026'!E4) -> 2483.8845 | V4: =+U4/M4 -> 354.84065 | W4: Romania | X4: 21 Jan 2026 10:39 | Y4: 20 Jan 2026 | Z4: =MID(X4,4,3) -> Jan | AA4: =IF($I4=AA$1,IF($L4=AA$1,$M4,$O4),IF($L4=AA$1,$P4,0)) -> 0 | AB4: =IF($I4=AB$1,IF($L4=AB$1,$M4,$O4),IF($L4=AB$1,$P4,0)) -> 7 | AC4: =IF($I4=AC$1,IF($L4=AC$1,$M4,$O4),IF($L4=AC$1,$P4,0)) -> 0 | AD4: =IF($I4=AD$1,IF($L4=AD$1,$M4,$O4),IF($L4=AD$1,$P4,0)) -> 0 | AE4: =IF($I4=AE$1,IF($L4=AE$1,$M4,$O4),IF($L4=AE$1,$P4,0)) -> 0 | AF4: =SUM(AA4:AE4) -> 7 | AG4: =+AF4-M4 -> 0 | AH4: =LEFT(X4,2)&"."&VLOOKUP(MID(X4,4,3),'Data validation'!$A$1:$B$12,2,FALSE)&".2025" -> 21.01.2025 | AI4: =WEEKNUM(AH4) -> 4 | AJ4: =H4&"."&VLOOKUP(I4,'Data validation'!$A$1:$B$12,2,FALSE)&".2026" -> 23.06.2026 | AK4: =WEEKNUM(AJ4) -> 26 | AL4: =VLOOKUP(E4,[2]Sheet1!$A:$B,2,FALSE) -> #N/A
A5: =VLOOKUP(Q5,'Data validation'!$K$2:$L$50,2,FALSE) -> TO | B5: =AA5+IF(I5="Jun",IF(_xlfn.NUMBERVALUE(H5)>14,0,IF(_xlfn.NUMBERVALUE(K5)<14,M5,15-_xlfn.NUMBERVALUE(H5))),0) -> 0 | C5: =M5-B5-D5 -> 5 | D5: =IF(L5="Jul",IF(_xlfn.NUMBERVALUE(K5)<11,0,IF(I5="Jul",IF(_xlfn.NUMBERVALUE(H5)>11,M5,_xlfn.NUMBERVALUE(K5)-11),0)),0)+IF(L5="Aug",IF(_xlfn.NUMBERVALUE(K5)>24,IF(_xlfn.NUMBERVALUE(H5)>24,0,25-_xlfn.NUMBERVALUE(H5)),IF(I5="Aug",M5,_xlfn.NUMBERVALUE(K5)-1+32-_xlfn.NUMBERVALUE(H5))),0) -> 0 | E5: 8231 | F5: 1173107.220477 | G5: 04 Jul 2026 | H5: =LEFT(G5,2) -> 04 | I5: =MID(G5,4,3) -> Jul | J5: 09 Jul 2026 | K5: =LEFT(J5,2) -> 09 | L5: =MID(J5,4,3) -> Jul | M5: 5 | N5: =+K5-H5 -> 5 | O5: =IF(I5=L5,0,31-H5) -> 0 | P5: =IF(I5=L5,0,K5-1) -> 0 | Q5: СЛР-ХОЛИДЕЙ-СЪРВИС ЕООД | R5: ROOM-SEA | S5: 2 | T5: 0 | U5: =SUMIFS(SLR!L:L,SLR!D:D,'Резервации 2026'!E5) -> 1238.1382 | V5: =+U5/M5 -> 247.62764 | W5: Romania | X5: 07 Nov 2025 22:18 | Y5: 07 Nov 2025 | Z5: =MID(X5,4,3) -> Nov | AA5: =IF($I5=AA$1,IF($L5=AA$1,$M5,$O5),IF($L5=AA$1,$P5,0)) -> 0 | AB5: =IF($I5=AB$1,IF($L5=AB$1,$M5,$O5),IF($L5=AB$1,$P5,0)) -> 0 | AC5: =IF($I5=AC$1,IF($L5=AC$1,$M5,$O5),IF($L5=AC$1,$P5,0)) -> 5 | AD5: =IF($I5=AD$1,IF($L5=AD$1,$M5,$O5),IF($L5=AD$1,$P5,0)) -> 0 | AE5: =IF($I5=AE$1,IF($L5=AE$1,$M5,$O5),IF($L5=AE$1,$P5,0)) -> 0 | AF5: =SUM(AA5:AE5) -> 5 | AG5: =+AF5-M5 -> 0 | AH5: =LEFT(X5,2)&"."&VLOOKUP(MID(X5,4,3),'Data validation'!$A$1:$B$12,2,FALSE)&".2025" -> 07.11.2025 | AI5: =WEEKNUM(AH5) -> 45 | AJ5: =H5&"."&VLOOKUP(I5,'Data validation'!$A$1:$B$12,2,FALSE)&".2026" -> 04.07.2026 | AK5: =WEEKNUM(AJ5) -> 27 | AL5: =VLOOKUP(E5,[2]Sheet1!$A:$B,2,FALSE) -> #N/A
A6: =VLOOKUP(Q6,'Data validation'!$K$2:$L$50,2,FALSE) -> TO | B6: =AA6+IF(I6="Jun",IF(_xlfn.NUMBERVALUE(H6)>14,0,IF(_xlfn.NUMBERVALUE(K6)<14,M6,15-_xlfn.NUMBERVALUE(H6))),0) -> 0 | C6: =M6-B6-D6 -> 0 | D6: =IF(L6="Jul",IF(_xlfn.NUMBERVALUE(K6)<11,0,IF(I6="Jul",IF(_xlfn.NUMBERVALUE(H6)>11,M6,_xlfn.NUMBERVALUE(K6)-11),0)),0)+IF(L6="Aug",IF(_xlfn.NUMBERVALUE(K6)>24,IF(_xlfn.NUMBERVALUE(H6)>24,0,25-_xlfn.NUMBERVALUE(H6)),IF(I6="Aug",M6,_xlfn.NUMBERVALUE(K6)-1+32-_xlfn.NUMBERVALUE(H6))),0) -> 6 | E6: 8238 | F6: 1173268.220507 | G6: 11 Jul 2026 | H6: =LEFT(G6,2) -> 11 | I6: =MID(G6,4,3) -> Jul | J6: 17 Jul 2026 | K6: =LEFT(J6,2) -> 17 | L6: =MID(J6,4,3) -> Jul | M6: 6 | N6: =+K6-H6 -> 6 | O6: =IF(I6=L6,0,31-H6) -> 0 | P6: =IF(I6=L6,0,K6-1) -> 0 | Q6: СЛР-ХОЛИДЕЙ-СЪРВИС ЕООД | R6: APP1-POOL | S6: 2 | T6: 2 | U6: =SUMIFS(SLR!L:L,SLR!D:D,'Резервации 2026'!E6) -> 2050.9225 | V6: =+U6/M6 -> 341.82041 | W6: Romania | X6: 08 Nov 2025 19:00 | Y6: 08 Nov 2025 | Z6: =MID(X6,4,3) -> Nov | AA6: =IF($I6=AA$1,IF($L6=AA$1,$M6,$O6),IF($L6=AA$1,$P6,0)) -> 0 | AB6: =IF($I6=AB$1,IF($L6=AB$1,$M6,$O6),IF($L6=AB$1,$P6,0)) -> 0 | AC6: =IF($I6=AC$1,IF($L6=AC$1,$M6,$O6),IF($L6=AC$1,$P6,0)) -> 6 | AD6: =IF($I6=AD$1,IF($L6=AD$1,$M6,$O6),IF($L6=AD$1,$P6,0)) -> 0 | AE6: =IF($I6=AE$1,IF($L6=AE$1,$M6,$O6),IF($L6=AE$1,$P6,0)) -> 0 | AF6: =SUM(AA6:AE6) -> 6 | AG6: =+AF6-M6 -> 0 | AH6: =LEFT(X6,2)&"."&VLOOKUP(MID(X6,4,3),'Data validation'!$A$1:$B$12,2,FALSE)&".2025" -> 08.11.2025 | AI6: =WEEKNUM(AH6) -> 45 | AJ6: =H6&"."&VLOOKUP(I6,'Data validation'!$A$1:$B$12,2,FALSE)&".2026" -> 11.07.2026 | AK6: =WEEKNUM(AJ6) -> 28 | AL6: =VLOOKUP(E6,[2]Sheet1!$A:$B,2,FALSE) -> #N/A
A7: =VLOOKUP(Q7,'Data validation'!$K$2:$L$50,2,FALSE) -> TO | B7: =AA7+IF(I7="Jun",IF(_xlfn.NUMBERVALUE(H7)>14,0,IF(_xlfn.NUMBERVALUE(K7)<14,M7,15-_xlfn.NUMBERVALUE(H7))),0) -> 0 | C7: =M7-B7-D7 -> 0 | D7: =IF(L7="Jul",IF(_xlfn.NUMBERVALUE(K7)<11,0,IF(I7="Jul",IF(_xlfn.NUMBERVALUE(H7)>11,M7,_xlfn.NUMBERVALUE(K7)-11),0)),0)+IF(L7="Aug",IF(_xlfn.NUMBERVALUE(K7)>24,IF(_xlfn.NUMBERVALUE(H7)>24,0,25-_xlfn.NUMBERVALUE(H7)),IF(I7="Aug",M7,_xlfn.NUMBERVALUE(K7)-1+32-_xlfn.NUMBERVALUE(H7))),0) -> 5 | E7: 8230 | F7: 1173106.220476 | G7: 19 Jul 2026 | H7: =LEFT(G7,2) -> 19 | I7: =MID(G7,4,3) -> Jul | J7: 24 Jul 2026 | K7: =LEFT(J7,2) -> 24 | L7: =MID(J7,4,3) -> Jul | M7: 5 | N7: =+K7-H7 -> 5 | O7: =IF(I7=L7,0,31-H7) -> 0 | P7: =IF(I7=L7,0,K7-1) -> 0 | Q7: СЛР-ХОЛИДЕЙ-СЪРВИС ЕООД | R7: APP1-DELUXE | S7: 2 | T7: 2 | U7: =SUMIFS(SLR!L:L,SLR!D:D,'Резервации 2026'!E7) -> 1937.9342 | V7: =+U7/M7 -> 387.58683 | W7: Romania | X7: 07 Nov 2025 22:13 | Y7: 07 Nov 2025 | Z7: =MID(X7,4,3) -> Nov | AA7: =IF($I7=AA$1,IF($L7=AA$1,$M7,$O7),IF($L7=AA$1,$P7,0)) -> 0 | AB7: =IF($I7=AB$1,IF($L7=AB$1,$M7,$O7),IF($L7=AB$1,$P7,0)) -> 0 | AC7: =IF($I7=AC$1,IF($L7=AC$1,$M7,$O7),IF($L7=AC$1,$P7,0)) -> 5 | AD7: =IF($I7=AD$1,IF($L7=AD$1,$M7,$O7),IF($L7=AD$1,$P7,0)) -> 0 | AE7: =IF($I7=AE$1,IF($L7=AE$1,$M7,$O7),IF($L7=AE$1,$P7,0)) -> 0 | AF7: =SUM(AA7:AE7) -> 5 | AG7: =+AF7-M7 -> 0 | AH7: =LEFT(X7,2)&"."&VLOOKUP(MID(X7,4,3),'Data validation'!$A$1:$B$12,2,FALSE)&".2025" -> 07.11.2025 | AI7: =WEEKNUM(AH7) -> 45 | AJ7: =H7&"."&VLOOKUP(I7,'Data validation'!$A$1:$B$12,2,FALSE)&".2026" -> 19.07.2026 | AK7: =WEEKNUM(AJ7) -> 30 | AL7: =VLOOKUP(E7,[2]Sheet1!$A:$B,2,FALSE) -> #N/A
A8: =VLOOKUP(Q8,'Data validation'!$K$2:$L$50,2,FALSE) -> TO | B8: =AA8+IF(I8="Jun",IF(_xlfn.NUMBERVALUE(H8)>14,0,IF(_xlfn.NUMBERVALUE(K8)<14,M8,15-_xlfn.NUMBERVALUE(H8))),0) -> 0 | C8: =M8-B8-D8 -> 6 | D8: =IF(L8="Jul",IF(_xlfn.NUMBERVALUE(K8)<11,0,IF(I8="Jul",IF(_xlfn.NUMBERVALUE(H8)>11,M8,_xlfn.NUMBERVALUE(K8)-11),0)),0)+IF(L8="Aug",IF(_xlfn.NUMBERVALUE(K8)>24,IF(_xlfn.NUMBERVALUE(H8)>24,0,25-_xlfn.NUMBERVALUE(H8)),IF(I8="Aug",M8,_xlfn.NUMBERVALUE(K8)-1+32-_xlfn.NUMBERVALUE(H8))),0) -> 0 | E8: 9622 | F8: 00001039 | G8: 29 Jun 2026 | H8: =LEFT(G8,2) -> 29 | I8: =MID(G8,4,3) -> Jun | J8: 05 Jul 2026 | K8: =LEFT(J8,2) -> 05 | L8: =MID(J8,4,3) -> Jul | M8: 6 | N8: =+K8-H8 -> -24 | O8: =IF(I8=L8,0,31-H8) -> 2 | P8: =IF(I8=L8,0,K8-1) -> 4 | Q8: КЛУБ МАГЕЛАН - ООД | R8: ROOM | S8: 2 | T8: 0 | U8: =SUMIFS(Magelan!L:L,Magelan!D:D,'Резервации 2026'!E8) -> 1688.1942 | V8: =+U8/M8 -> 281.3657 | W8: Romania | X8: 21 Jan 2026 12:49 | Y8: 21 Jan 2026 | Z8: =MID(X8,4,3) -> Jan | AA8: =IF($I8=AA$1,IF($L8=AA$1,$M8,$O8),IF($L8=AA$1,$P8,0)) -> 0 | AB8: =IF($I8=AB$1,IF($L8=AB$1,$M8,$O8),IF($L8=AB$1,$P8,0)) -> 2 | AC8: =IF($I8=AC$1,IF($L8=AC$1,$M8,$O8),IF($L8=AC$1,$P8,0)) -> 4 | AD8: =IF($I8=AD$1,IF($L8=AD$1,$M8,$O8),IF($L8=AD$1,$P8,0)) -> 0 | AE8: =IF($I8=AE$1,IF($L8=AE$1,$M8,$O8),IF($L8=AE$1,$P8,0)) -> 0 | AF8: =SUM(AA8:AE8) -> 6 | AG8: =+AF8-M8 -> 0 | AH8: =LEFT(X8,2)&"."&VLOOKUP(MID(X8,4,3),'Data validation'!$A$1:$B$12,2,FALSE)&".2025" -> 21.01.2025 | AI8: =WEEKNUM(AH8) -> 4 | AJ8: =H8&"."&VLOOKUP(I8,'Data validation'!$A$1:$B$12,2,FALSE)&".2026" -> 29.06.2026 | AK8: =WEEKNUM(AJ8) -> 27 | AL8: =VLOOKUP(E8,[2]Sheet1!$A:$B,2,FALSE) -> #N/A
A9: =VLOOKUP(Q9,'Data validation'!$K$2:$L$50,2,FALSE) -> TO | B9: =AA9+IF(I9="Jun",IF(_xlfn.NUMBERVALUE(H9)>14,0,IF(_xlfn.NUMBERVALUE(K9)<14,M9,15-_xlfn.NUMBERVALUE(H9))),0) -> 0 | C9: =M9-B9-D9 -> 0 | D9: =IF(L9="Jul",IF(_xlfn.NUMBERVALUE(K9)<11,0,IF(I9="Jul",IF(_xlfn.NUMBERVALUE(H9)>11,M9,_xlfn.NUMBERVALUE(K9)-11),0)),0)+IF(L9="Aug",IF(_xlfn.NUMBERVALUE(K9)>24,IF(_xlfn.NUMBERVALUE(H9)>24,0,25-_xlfn.NUMBERVALUE(H9)),IF(I9="Aug",M9,_xlfn.NUMBERVALUE(K9)-1+32-_xlfn.NUMBERVALUE(H9))),0) -> 6 | E9: 8049 | F9: 1169860.219307 | G9: 20 Jul 2026 | H9: =LEFT(G9,2) -> 20 | I9: =MID(G9,4,3) -> Jul | J9: 26 Jul 2026 | K9: =LEFT(J9,2) -> 26 | L9: =MID(J9,4,3) -> Jul | M9: 6 | N9: =+K9-H9 -> 6 | O9: =IF(I9=L9,0,31-H9) -> 0 | P9: =IF(I9=L9,0,K9-1) -> 0 | Q9: СЛР-ХОЛИДЕЙ-СЪРВИС ЕООД | R9: ROOM | S9: 2 | T9: 1 | U9: =SUMIFS(SLR!L:L,SLR!D:D,'Резервации 2026'!E9) -> 1735.3688 | V9: =+U9/M9 -> 289.22814 | W9: Romania | X9: 27 Oct 2025 15:55 | Y9: 22 Oct 2025 | Z9: =MID(X9,4,3) -> Oct | AA9: =IF($I9=AA$1,IF($L9=AA$1,$M9,$O9),IF($L9=AA$1,$P9,0)) -> 0 | AB9: =IF($I9=AB$1,IF($L9=AB$1,$M9,$O9),IF($L9=AB$1,$P9,0)) -> 0 | AC9: =IF($I9=AC$1,IF($L9=AC$1,$M9,$O9),IF($L9=AC$1,$P9,0)) -> 6 | AD9: =IF($I9=AD$1,IF($L9=AD$1,$M9,$O9),IF($L9=AD$1,$P9,0)) -> 0 | AE9: =IF($I9=AE$1,IF($L9=AE$1,$M9,$O9),IF($L9=AE$1,$P9,0)) -> 0 | AF9: =SUM(AA9:AE9) -> 6 | AG9: =+AF9-M9 -> 0 | AH9: =LEFT(X9,2)&"."&VLOOKUP(MID(X9,4,3),'Data validation'!$A$1:$B$12,2,FALSE)&".2025" -> 27.10.2025 | AI9: =WEEKNUM(AH9) -> 44 | AJ9: =H9&"."&VLOOKUP(I9,'Data validation'!$A$1:$B$12,2,FALSE)&".2026" -> 20.07.2026 | AK9: =WEEKNUM(AJ9) -> 30 | AL9: =VLOOKUP(E9,[2]Sheet1!$A:$B,2,FALSE) -> #N/A
A10: =VLOOKUP(Q10,'Data validation'!$K$2:$L$50,2,FALSE) -> TO | B10: =AA10+IF(I10="Jun",IF(_xlfn.NUMBERVALUE(H10)>14,0,IF(_xlfn.NUMBERVALUE(K10)<14,M10,15-_xlfn.NUMBERVALUE(H10))),0) -> 0 | C10: =M10-B10-D10 -> 0 | D10: =IF(L10="Jul",IF(_xlfn.NUMBERVALUE(K10)<11,0,IF(I10="Jul",IF(_xlfn.NUMBERVALUE(H10)>11,M10,_xlfn.NUMBERVALUE(K10)-11),0)),0)+IF(L10="Aug",IF(_xlfn.NUMBERVALUE(K10)>24,IF(_xlfn.NUMBERVALUE(H10)>24,0,25-_xlfn.NUMBERVALUE(H10)),IF(I10="Aug",M10,_xlfn.NUMBERVALUE(K10)-1+32-_xlfn.NUMBERVALUE(H10))),0) -> 6 | E10: 8050 | F10: 1169861.219308 | G10: 20 Jul 2026 | H10: =LEFT(G10,2) -> 20 | I10: =MID(G10,4,3) -> Jul | J10: 26 Jul 2026 | K10: =LEFT(J10,2) -> 26 | L10: =MID(J10,4,3) -> Jul | M10: 6 | N10: =+K10-H10 -> 6 | O10: =IF(I10=L10,0,31-H10) -> 0 | P10: =IF(I10=L10,0,K10-1) -> 0 | Q10: СЛР-ХОЛИДЕЙ-СЪРВИС ЕООД | R10: ROOM | S10: 3 | T10: 1 | U10: =SUMIFS(SLR!L:L,SLR!D:D,'Резервации 2026'!E10) -> 2342.7714 | V10: =+U10/M10 -> 390.4619 | W10: Romania | X10: 27 Oct 2025 15:55 | Y10: 22 Oct 2025 | Z10: =MID(X10,4,3) -> Oct | AA10: =IF($I10=AA$1,IF($L10=AA$1,$M10,$O10),IF($L10=AA$1,$P10,0)) -> 0 | AB10: =IF($I10=AB$1,IF($L10=AB$1,$M10,$O10),IF($L10=AB$1,$P10,0)) -> 0 | AC10: =IF($I10=AC$1,IF($L10=AC$1,$M10,$O10),IF($L10=AC$1,$P10,0)) -> 6 | AD10: =IF($I10=AD$1,IF($L10=AD$1,$M10,$O10),IF($L10=AD$1,$P10,0)) -> 0 | AE10: =IF($I10=AE$1,IF($L10=AE$1,$M10,$O10),IF($L10=AE$1,$P10,0)) -> 0 | AF10: =SUM(AA10:AE10) -> 6 | AG10: =+AF10-M10 -> 0 | AH10: =LEFT(X10,2)&"."&VLOOKUP(MID(X10,4,3),'Data validation'!$A$1:$B$12,2,FALSE)&".2025" -> 27.10.2025 | AI10: =WEEKNUM(AH10) -> 44 | AJ10: =H10&"."&VLOOKUP(I10,'Data validation'!$A$1:$B$12,2,FALSE)&".2026" -> 20.07.2026 | AK10: =WEEKNUM(AJ10) -> 30 | AL10: =VLOOKUP(E10,[2]Sheet1!$A:$B,2,FALSE) -> #N/A
A11: =VLOOKUP(Q11,'Data validation'!$K$2:$L$50,2,FALSE) -> TO | B11: =AA11+IF(I11="Jun",IF(_xlfn.NUMBERVALUE(H11)>14,0,IF(_xlfn.NUMBERVALUE(K11)<14,M11,15-_xlfn.NUMBERVALUE(H11))),0) -> 0 | C11: =M11-B11-D11 -> 0 | D11: =IF(L11="Jul",IF(_xlfn.NUMBERVALUE(K11)<11,0,IF(I11="Jul",IF(_xlfn.NUMBERVALUE(H11)>11,M11,_xlfn.NUMBERVALUE(K11)-11),0)),0)+IF(L11="Aug",IF(_xlfn.NUMBERVALUE(K11)>24,IF(_xlfn.NUMBERVALUE(H11)>24,0,25-_xlfn.NUMBERVALUE(H11)),IF(I11="Aug",M11,_xlfn.NUMBERVALUE(K11)-1+32-_xlfn.NUMBERVALUE(H11))),0) -> 6 | E11: 8055 | F11: 1170038.219412 | G11: 20 Jul 2026 | H11: =LEFT(G11,2) -> 20 | I11: =MID(G11,4,3) -> Jul | J11: 26 Jul 2026 | K11: =LEFT(J11,2) -> 26 | L11: =MID(J11,4,3) -> Jul | M11: 6 | N11: =+K11-H11 -> 6 | O11: =IF(I11=L11,0,31-H11) -> 0 | P11: =IF(I11=L11,0,K11-1) -> 0 | Q11: СЛР-ХОЛИДЕЙ-СЪРВИС ЕООД | R11: ROOM | S11: 3 | T11: 1 | U11: =SUMIFS(SLR!L:L,SLR!D:D,'Резервации 2026'!E11) -> 2342.7714 | V11: =+U11/M11 -> 390.4619 | W11: Romania | X11: 27 Oct 2025 15:55 | Y11: 23 Oct 2025 | Z11: =MID(X11,4,3) -> Oct | AA11: =IF($I11=AA$1,IF($L11=AA$1,$M11,$O11),IF($L11=AA$1,$P11,0)) -> 0 | AB11: =IF($I11=AB$1,IF($L11=AB$1,$M11,$O11),IF($L11=AB$1,$P11,0)) -> 0 | AC11: =IF($I11=AC$1,IF($L11=AC$1,$M11,$O11),IF($L11=AC$1,$P11,0)) -> 6 | AD11: =IF($I11=AD$1,IF($L11=AD$1,$M11,$O11),IF($L11=AD$1,$P11,0)) -> 0 | AE11: =IF($I11=AE$1,IF($L11=AE$1,$M11,$O11),IF($L11=AE$1,$P11,0)) -> 0 | AF11: =SUM(AA11:AE11) -> 6 | AG11: =+AF11-M11 -> 0 | AH11: =LEFT(X11,2)&"."&VLOOKUP(MID(X11,4,3),'Data validation'!$A$1:$B$12,2,FALSE)&".2025" -> 27.10.2025 | AI11: =WEEKNUM(AH11) -> 44 | AJ11: =H11&"."&VLOOKUP(I11,'Data validation'!$A$1:$B$12,2,FALSE)&".2026" -> 20.07.2026 | AK11: =WEEKNUM(AJ11) -> 30 | AL11: =VLOOKUP(E11,[2]Sheet1!$A:$B,2,FALSE) -> #N/A
A12: =VLOOKUP(Q12,'Data validation'!$K$2:$L$50,2,FALSE) -> TO | B12: =AA12+IF(I12="Jun",IF(_xlfn.NUMBERVALUE(H12)>14,0,IF(_xlfn.NUMBERVALUE(K12)<14,M12,15-_xlfn.NUMBERVALUE(H12))),0) -> 0 | C12: =M12-B12-D12 -> 0 | D12: =IF(L12="Jul",IF(_xlfn.NUMBERVALUE(K12)<11,0,IF(I12="Jul",IF(_xlfn.NUMBERVALUE(H12)>11,M12,_xlfn.NUMBERVALUE(K12)-11),0)),0)+IF(L12="Aug",IF(_xlfn.NUMBERVALUE(K12)>24,IF(_xlfn.NUMBERVALUE(H12)>24,0,25-_xlfn.NUMBERVALUE(H12)),IF(I12="Aug",M12,_xlfn.NUMBERVALUE(K12)-1+32-_xlfn.NUMBERVALUE(H12))),0) -> 6 | E12: 8057 | F12: 1170169.219532 | G12: 20 Jul 2026 | H12: =LEFT(G12,2) -> 20 | I12: =MID(G12,4,3) -> Jul | J12: 26 Jul 2026 | K12: =LEFT(J12,2) -> 26 | L12: =MID(J12,4,3) -> Jul | M12: 6 | N12: =+K12-H12 -> 6 | O12: =IF(I12=L12,0,31-H12) -> 0 | P12: =IF(I12=L12,0,K12-1) -> 0 | Q12: СЛР-ХОЛИДЕЙ-СЪРВИС ЕООД | R12: ROOM-DELUXE | S12: 2 | T12: 1 | U12: =SUMIFS(SLR!L:L,SLR!D:D,'Резервации 2026'!E12) -> 1805.544 | V12: =+U12/M12 -> 300.924 | W12: Romania | X12: 27 Oct 2025 15:56 | Y12: 24 Oct 2025 | Z12: =MID(X12,4,3) -> Oct | AA12: =IF($I12=AA$1,IF($L12=AA$1,$M12,$O12),IF($L12=AA$1,$P12,0)) -> 0 | AB12: =IF($I12=AB$1,IF($L12=AB$1,$M12,$O12),IF($L12=AB$1,$P12,0)) -> 0 | AC12: =IF($I12=AC$1,IF($L12=AC$1,$M12,$O12),IF($L12=AC$1,$P12,0)) -> 6 | AD12: =IF($I12=AD$1,IF($L12=AD$1,$M12,$O12),IF($L12=AD$1,$P12,0)) -> 0 | AE12: =IF($I12=AE$1,IF($L12=AE$1,$M12,$O12),IF($L12=AE$1,$P12,0)) -> 0 | AF12: =SUM(AA12:AE12) -> 6 | AG12: =+AF12-M12 -> 0 | AH12: =LEFT(X12,2)&"."&VLOOKUP(MID(X12,4,3),'Data validation'!$A$1:$B$12,2,FALSE)&".2025" -> 27.10.2025 | AI12: =WEEKNUM(AH12) -> 44 | AJ12: =H12&"."&VLOOKUP(I12,'Data validation'!$A$1:$B$12,2,FALSE)&".2026" -> 20.07.2026 | AK12: =WEEKNUM(AJ12) -> 30 | AL12: =VLOOKUP(E12,[2]Sheet1!$A:$B,2,FALSE) -> #N/A
A13: =VLOOKUP(Q13,'Data validation'!$K$2:$L$50,2,FALSE) -> TO | B13: =AA13+IF(I13="Jun",IF(_xlfn.NUMBERVALUE(H13)>14,0,IF(_xlfn.NUMBERVALUE(K13)<14,M13,15-_xlfn.NUMBERVALUE(H13))),0) -> 0 | C13: =M13-B13-D13 -> 0 | D13: =IF(L13="Jul",IF(_xlfn.NUMBERVALUE(K13)<11,0,IF(I13="Jul",IF(_xlfn.NUMBERVALUE(H13)>11,M13,_xlfn.NUMBERVALUE(K13)-11),0)),0)+IF(L13="Aug",IF(_xlfn.NUMBERVALUE(K13)>24,IF(_xlfn.NUMBERVALUE(H13)>24,0,25-_xlfn.NUMBERVALUE(H13)),IF(I13="Aug",M13,_xlfn.NUMBERVALUE(K13)-1+32-_xlfn.NUMBERVALUE(H13))),0) -> 5 | E13: 9975 | F13: 1240128.232930 | G13: 27 Jul 2026 | H13: =LEFT(G13,2) -> 27 | I13: =MID(G13,4,3) -> Jul | J13: 01 Aug 2026 | K13: =LEFT(J13,2) -> 01 | L13: =MID(J13,4,3) -> Aug | M13: 5 | N13: =+K13-H13 -> -26 | O13: =IF(I13=L13,0,31-H13) -> 4 | P13: =IF(I13=L13,0,K13-1) -> 0 | Q13: СЛР-ХОЛИДЕЙ-СЪРВИС ЕООД | R13: ROOM | S13: 1 | T13: 0 | U13: =SUMIFS(SLR!L:L,SLR!D:D,'Резервации 2026'!E13) -> 1168.1195 | V13: =+U13/M13 -> 233.62389 | W13: Romania | X13: 02 Feb 2026 15:23 | Y13: 02 Feb 2026 | Z13: =MID(X13,4,3) -> Feb | AA13: =IF($I13=AA$1,IF($L13=AA$1,$M13,$O13),IF($L13=AA$1,$P13,0)) -> 0 | AB13: =IF($I13=AB$1,IF($L13=AB$1,$M13,$O13),IF($L13=AB$1,$P13,0)) -> 0 | AC13: =IF($I13=AC$1,IF($L13=AC$1,$M13,$O13),IF($L13=AC$1,$P13,0)) -> 4 | AD13: =IF($I13=AD$1,IF($L13=AD$1,$M13,$O13),IF($L13=AD$1,$P13,0)) -> 0 | AE13: =IF($I13=AE$1,IF($L13=AE$1,$M13,$O13),IF($L13=AE$1,$P13,0)) -> 0 | AF13: =SUM(AA13:AE13) -> 4 | AG13: =+AF13-M13 -> -1 | AH13: =LEFT(X13,2)&"."&VLOOKUP(MID(X13,4,3),'Data validation'!$A$1:$B$12,2,FALSE)&".2025" -> 02.02.2025 | AI13: =WEEKNUM(AH13) -> 6 | AJ13: =H13&"."&VLOOKUP(I13,'Data validation'!$A$1:$B$12,2,FALSE)&".2026" -> 27.07.2026 | AK13: =WEEKNUM(AJ13) -> 31 | AL13: =VLOOKUP(E13,[2]Sheet1!$A:$B,2,FALSE) -> #N/A
A14: =VLOOKUP(Q14,'Data validation'!$K$2:$L$50,2,FALSE) -> TO | B14: =AA14+IF(I14="Jun",IF(_xlfn.NUMBERVALUE(H14)>14,0,IF(_xlfn.NUMBERVALUE(K14)<14,M14,15-_xlfn.NUMBERVALUE(H14))),0) -> 0 | C14: =M14-B14-D14 -> 0 | D14: =IF(L14="Jul",IF(_xlfn.NUMBERVALUE(K14)<11,0,IF(I14="Jul",IF(_xlfn.NUMBERVALUE(H14)>11,M14,_xlfn.NUMBERVALUE(K14)-11),0)),0)+IF(L14="Aug",IF(_xlfn.NUMBERVALUE(K14)>24,IF(_xlfn.NUMBERVALUE(H14)>24,0,25-_xlfn.NUMBERVALUE(H14)),IF(I14="Aug",M14,_xlfn.NUMBERVALUE(K14)-1+32-_xlfn.NUMBERVALUE(H14))),0) -> 6 | E14: 9628 | F14: 18659 | G14: 10 Aug 2026 | H14: =LEFT(G14,2) -> 10 | I14: =MID(G14,4,3) -> Aug | J14: 16 Aug 2026 | K14: =LEFT(J14,2) -> 16 | L14: =MID(J14,4,3) -> Aug | M14: 6 | N14: =+K14-H14 -> 6 | O14: =IF(I14=L14,0,31-H14) -> 0 | P14: =IF(I14=L14,0,K14-1) -> 0 | Q14: КЛУБ МАГЕЛАН - ООД | R14: ROOM-SEA | S14: 3 | T14: 1 | U14: =SUMIFS(Magelan!L:L,Magelan!D:D,'Резервации 2026'!E14) -> 2584.1599 | V14: =+U14/M14 -> 430.69332 | W14: Romania | X14: 21 Jan 2026 16:25 | Y14: 21 Jan 2026 | Z14: =MID(X14,4,3) -> Jan | AA14: =IF($I14=AA$1,IF($L14=AA$1,$M14,$O14),IF($L14=AA$1,$P14,0)) -> 0 | AB14: =IF($I14=AB$1,IF($L14=AB$1,$M14,$O14),IF($L14=AB$1,$P14,0)) -> 0 | AC14: =IF($I14=AC$1,IF($L14=AC$1,$M14,$O14),IF($L14=AC$1,$P14,0)) -> 0 | AD14: =IF($I14=AD$1,IF($L14=AD$1,$M14,$O14),IF($L14=AD$1,$P14,0)) -> 6 | AE14: =IF($I14=AE$1,IF($L14=AE$1,$M14,$O14),IF($L14=AE$1,$P14,0)) -> 0 | AF14: =SUM(AA14:AE14) -> 6 | AG14: =+AF14-M14 -> 0 | AH14: =LEFT(X14,2)&"."&VLOOKUP(MID(X14,4,3),'Data validation'!$A$1:$B$12,2,FALSE)&".2025" -> 21.01.2025 | AI14: =WEEKNUM(AH14) -> 4 | AJ14: =H14&"."&VLOOKUP(I14,'Data validation'!$A$1:$B$12,2,FALSE)&".2026" -> 10.08.2026 | AK14: =WEEKNUM(AJ14) -> 33 | AL14: =VLOOKUP(E14,[2]Sheet1!$A:$B,2,FALSE) -> #N/A
A15: =VLOOKUP(Q15,'Data validation'!$K$2:$L$50,2,FALSE) -> TO | B15: =AA15+IF(I15="Jun",IF(_xlfn.NUMBERVALUE(H15)>14,0,IF(_xlfn.NUMBERVALUE(K15)<14,M15,15-_xlfn.NUMBERVALUE(H15))),0) -> 0 | C15: =M15-B15-D15 -> 0 | D15: =IF(L15="Jul",IF(_xlfn.NUMBERVALUE(K15)<11,0,IF(I15="Jul",IF(_xlfn.NUMBERVALUE(H15)>11,M15,_xlfn.NUMBERVALUE(K15)-11),0)),0)+IF(L15="Aug",IF(_xlfn.NUMBERVALUE(K15)>24,IF(_xlfn.NUMBERVALUE(H15)>24,0,25-_xlfn.NUMBERVALUE(H15)),IF(I15="Aug",M15,_xlfn.NUMBERVALUE(K15)-1+32-_xlfn.NUMBERVALUE(H15))),0) -> 6 | E15: 8127 | F15: 1170906.219838 | G15: 20 Jul 2026 | H15: =LEFT(G15,2) -> 20 | I15: =MID(G15,4,3) -> Jul | J15: 26 Jul 2026 | K15: =LEFT(J15,2) -> 26 | L15: =MID(J15,4,3) -> Jul | M15: 6 | N15: =+K15-H15 -> 6 | O15: =IF(I15=L15,0,31-H15) -> 0 | P15: =IF(I15=L15,0,K15-1) -> 0 | Q15: СЛР-ХОЛИДЕЙ-СЪРВИС ЕООД | R15: ROOM | S15: 2 | T15: 1 | U15: =SUMIFS(SLR!L:L,SLR!D:D,'Резервации 2026'!E15) -> 1735.3688 | V15: =+U15/M15 -> 289.22814 | W15: Romania | X15: 03 Nov 2025 10:08 | Y15: 31 Oct 2025 | Z15: =MID(X15,4,3) -> Nov | AA15: =IF($I15=AA$1,IF($L15=AA$1,$M15,$O15),IF($L15=AA$1,$P15,0)) -> 0 | AB15: =IF($I15=AB$1,IF($L15=AB$1,$M15,$O15),IF($L15=AB$1,$P15,0)) -> 0 | AC15: =IF($I15=AC$1,IF($L15=AC$1,$M15,$O15),IF($L15=AC$1,$P15,0)) -> 6 | AD15: =IF($I15=AD$1,IF($L15=AD$1,$M15,$O15),IF($L15=AD$1,$P15,0)) -> 0 | AE15: =IF($I15=AE$1,IF($L15=AE$1,$M15,$O15),IF($L15=AE$1,$P15,0)) -> 0 | AF15: =SUM(AA15:AE15) -> 6 | AG15: =+AF15-M15 -> 0 | AH15: =LEFT(X15,2)&"."&VLOOKUP(MID(X15,4,3),'Data validation'!$A$1:$B$12,2,FALSE)&".2025" -> 03.11.2025 | AI15: =WEEKNUM(AH15) -> 45 | AJ15: =H15&"."&VLOOKUP(I15,'Data validation'!$A$1:$B$12,2,FALSE)&".2026" -> 20.07.2026 | AK15: =WEEKNUM(AJ15) -> 30 | AL15: =VLOOKUP(E15,[2]Sheet1!$A:$B,2,FALSE) -> #N/A
A16: =VLOOKUP(Q16,'Data validation'!$K$2:$L$50,2,FALSE) -> TO | B16: =AA16+IF(I16="Jun",IF(_xlfn.NUMBERVALUE(H16)>14,0,IF(_xlfn.NUMBERVALUE(K16)<14,M16,15-_xlfn.NUMBERVALUE(H16))),0) -> 0 | C16: =M16-B16-D16 -> 5 | D16: =IF(L16="Jul",IF(_xlfn.NUMBERVALUE(K16)<11,0,IF(I16="Jul",IF(_xlfn.NUMBERVALUE(H16)>11,M16,_xlfn.NUMBERVALUE(K16)-11),0)),0)+IF(L16="Aug",IF(_xlfn.NUMBERVALUE(K16)>24,IF(_xlfn.NUMBERVALUE(H16)>24,0,25-_xlfn.NUMBERVALUE(H16)),IF(I16="Aug",M16,_xlfn.NUMBERVALUE(K16)-1+32-_xlfn.NUMBERVALUE(H16))),0) -> 0 | E16: 10333 | F16: 28971 | G16: 22 Jun 2026 | H16: =LEFT(G16,2) -> 22 | I16: =MID(G16,4,3) -> Jun | J16: 27 Jun 2026 | K16: =LEFT(J16,2) -> 27 | L16: =MID(J16,4,3) -> Jun | M16: 5 | N16: =+K16-H16 -> 5 | O16: =IF(I16=L16,0,31-H16) -> 0 | P16: =IF(I16=L16,0,K16-1) -> 0 | Q16: КЛУБ МАГЕЛАН - ООД | R16: ROOM-SEA | S16: 2 | T16: 0 | U16: =SUMIFS(Magelan!L:L,Magelan!D:D,'Резервации 2026'!E16) -> 1434.6404 | V16: =+U16/M16 -> 286.92808 | W16: Romania | X16: 04 Mar 2026 17:24 | Y16: 04 Mar 2026 | Z16: =MID(X16,4,3) -> Mar | AA16: =IF($I16=AA$1,IF($L16=AA$1,$M16,$O16),IF($L16=AA$1,$P16,0)) -> 0 | AB16: =IF($I16=AB$1,IF($L16=AB$1,$M16,$O16),IF($L16=AB$1,$P16,0)) -> 5 | AC16: =IF($I16=AC$1,IF($L16=AC$1,$M16,$O16),IF($L16=AC$1,$P16,0)) -> 0 | AD16: =IF($I16=AD$1,IF($L16=AD$1,$M16,$O16),IF($L16=AD$1,$P16,0)) -> 0 | AE16: =IF($I16=AE$1,IF($L16=AE$1,$M16,$O16),IF($L16=AE$1,$P16,0)) -> 0 | AF16: =SUM(AA16:AE16) -> 5 | AG16: =+AF16-M16 -> 0 | AH16: =LEFT(X16,2)&"."&VLOOKUP(MID(X16,4,3),'Data validation'!$A$1:$B$12,2,FALSE)&".2025" -> 04.03.2025 | AI16: =WEEKNUM(AH16) -> 10 | AJ16: =H16&"."&VLOOKUP(I16,'Data validation'!$A$1:$B$12,2,FALSE)&".2026" -> 22.06.2026 | AK16: =WEEKNUM(AJ16) -> 26 | AL16: =VLOOKUP(E16,[2]Sheet1!$A:$B,2,FALSE) -> #N/A
A17: =VLOOKUP(Q17,'Data validation'!$K$2:$L$50,2,FALSE) -> TO | B17: =AA17+IF(I17="Jun",IF(_xlfn.NUMBERVALUE(H17)>14,0,IF(_xlfn.NUMBERVALUE(K17)<14,M17,15-_xlfn.NUMBERVALUE(H17))),0) -> 0 | C17: =M17-B17-D17 -> 0 | D17: =IF(L17="Jul",IF(_xlfn.NUMBERVALUE(K17)<11,0,IF(I17="Jul",IF(_xlfn.NUMBERVALUE(H17)>11,M17,_xlfn.NUMBERVALUE(K17)-11),0)),0)+IF(L17="Aug",IF(_xlfn.NUMBERVALUE(K17)>24,IF(_xlfn.NUMBERVALUE(H17)>24,0,25-_xlfn.NUMBERVALUE(H17)),IF(I17="Aug",M17,_xlfn.NUMBERVALUE(K17)-1+32-_xlfn.NUMBERVALUE(H17))),0) -> 5 | E17: 9510 | F17: NT314343 | G17: 27 Jul 2026 | H17: =LEFT(G17,2) -> 27 | I17: =MID(G17,4,3) -> Jul | J17: 01 Aug 2026 | K17: =LEFT(J17,2) -> 01 | L17: =MID(J17,4,3) -> Aug | M17: 5 | N17: =+K17-H17 -> -26 | O17: =IF(I17=L17,0,31-H17) -> 4 | P17: =IF(I17=L17,0,K17-1) -> 0 | Q17: НОВОТОН - ЕООД | R17: ROOM | S17: 2 | T17: 0 | U17: =SUMIFS(Novoton!L:L,Novoton!D:D,'Резервации 2026'!E17) -> 0 | V17: =+U17/M17 -> 0 | W17: Romania | X17: 15 Jan 2026 11:25 | Y17: 15 Jan 2026 | Z17: =MID(X17,4,3) -> Jan | AA17: =IF($I17=AA$1,IF($L17=AA$1,$M17,$O17),IF($L17=AA$1,$P17,0)) -> 0 | AB17: =IF($I17=AB$1,IF($L17=AB$1,$M17,$O17),IF($L17=AB$1,$P17,0)) -> 0 | AC17: =IF($I17=AC$1,IF($L17=AC$1,$M17,$O17),IF($L17=AC$1,$P17,0)) -> 4 | AD17: =IF($I17=AD$1,IF($L17=AD$1,$M17,$O17),IF($L17=AD$1,$P17,0)) -> 0 | AE17: =IF($I17=AE$1,IF($L17=AE$1,$M17,$O17),IF($L17=AE$1,$P17,0)) -> 0 | AF17: =SUM(AA17:AE17) -> 4 | AG17: =+AF17-M17 -> -1 | AH17: =LEFT(X17,2)&"."&VLOOKUP(MID(X17,4,3),'Data validation'!$A$1:$B$12,2,FALSE)&".2025" -> 15.01.2025 | AI17: =WEEKNUM(AH17) -> 3 | AJ17: =H17&"."&VLOOKUP(I17,'Data validation'!$A$1:$B$12,2,FALSE)&".2026" -> 27.07.2026 | AK17: =WEEKNUM(AJ17) -> 31 | AL17: =VLOOKUP(E17,[2]Sheet1!$A:$B,2,FALSE) -> Анулирана
A18: =VLOOKUP(Q18,'Data validation'!$K$2:$L$50,2,FALSE) -> TO | B18: =AA18+IF(I18="Jun",IF(_xlfn.NUMBERVALUE(H18)>14,0,IF(_xlfn.NUMBERVALUE(K18)<14,M18,15-_xlfn.NUMBERVALUE(H18))),0) -> 0 | C18: =M18-B18-D18 -> 6 | D18: =IF(L18="Jul",IF(_xlfn.NUMBERVALUE(K18)<11,0,IF(I18="Jul",IF(_xlfn.NUMBERVALUE(H18)>11,M18,_xlfn.NUMBERVALUE(K18)-11),0)),0)+IF(L18="Aug",IF(_xlfn.NUMBERVALUE(K18)>24,IF(_xlfn.NUMBERVALUE(H18)>24,0,25-_xlfn.NUMBERVALUE(H18)),IF(I18="Aug",M18,_xlfn.NUMBERVALUE(K18)-1+32-_xlfn.NUMBERVALUE(H18))),0) -> 0 | E18: 9630 | F18: 52373 | G18: 29 Jun 2026 | H18: =LEFT(G18,2) -> 29 | I18: =MID(G18,4,3) -> Jun | J18: 05 Jul 2026 | K18: =LEFT(J18,2) -> 05 | L18: =MID(J18,4,3) -> Jul | M18: 6 | N18: =+K18-H18 -> -24 | O18: =IF(I18=L18,0,31-H18) -> 2 | P18: =IF(I18=L18,0,K18-1) -> 4 | Q18: КЛУБ МАГЕЛАН - ООД | R18: ROOM-SEA | S18: 2 | T18: 1 | U18: =SUMIFS(Magelan!L:L,Magelan!D:D,'Резервации 2026'!E18) -> 1733.2565 | V18: =+U18/M18 -> 288.87609 | W18: Romania | X18: 21 Jan 2026 16:51 | Y18: 21 Jan 2026 | Z18: =MID(X18,4,3) -> Jan | AA18: =IF($I18=AA$1,IF($L18=AA$1,$M18,$O18),IF($L18=AA$1,$P18,0)) -> 0 | AB18: =IF($I18=AB$1,IF($L18=AB$1,$M18,$O18),IF($L18=AB$1,$P18,0)) -> 2 | AC18: =IF($I18=AC$1,IF($L18=AC$1,$M18,$O18),IF($L18=AC$1,$P18,0)) -> 4 | AD18: =IF($I18=AD$1,IF($L18=AD$1,$M18,$O18),IF($L18=AD$1,$P18,0)) -> 0 | AE18: =IF($I18=AE$1,IF($L18=AE$1,$M18,$O18),IF($L18=AE$1,$P18,0)) -> 0 | AF18: =SUM(AA18:AE18) -> 6 | AG18: =+AF18-M18 -> 0 | AH18: =LEFT(X18,2)&"."&VLOOKUP(MID(X18,4,3),'Data validation'!$A$1:$B$12,2,FALSE)&".2025" -> 21.01.2025 | AI18: =WEEKNUM(AH18) -> 4 | AJ18: =H18&"."&VLOOKUP(I18,'Data validation'!$A$1:$B$12,2,FALSE)&".2026" -> 29.06.2026 | AK18: =WEEKNUM(AJ18) -> 27 | AL18: =VLOOKUP(E18,[2]Sheet1!$A:$B,2,FALSE) -> #N/A
A19: =VLOOKUP(Q19,'Data validation'!$K$2:$L$50,2,FALSE) -> TO | B19: =AA19+IF(I19="Jun",IF(_xlfn.NUMBERVALUE(H19)>14,0,IF(_xlfn.NUMBERVALUE(K19)<14,M19,15-_xlfn.NUMBERVALUE(H19))),0) -> 0 | C19: =M19-B19-D19 -> 6 | D19: =IF(L19="Jul",IF(_xlfn.NUMBERVALUE(K19)<11,0,IF(I19="Jul",IF(_xlfn.NUMBERVALUE(H19)>11,M19,_xlfn.NUMBERVALUE(K19)-11),0)),0)+IF(L19="Aug",IF(_xlfn.NUMBERVALUE(K19)>24,IF(_xlfn.NUMBERVALUE(H19)>24,0,25-_xlfn.NUMBERVALUE(H19)),IF(I19="Aug",M19,_xlfn.NUMBERVALUE(K19)-1+32-_xlfn.NUMBERVALUE(H19))),0) -> 0 | E19: 9631 | F19: 52374 | G19: 29 Jun 2026 | H19: =LEFT(G19,2) -> 29 | I19: =MID(G19,4,3) -> Jun | J19: 05 Jul 2026 | K19: =LEFT(J19,2) -> 05 | L19: =MID(J19,4,3) -> Jul | M19: 6 | N19: =+K19-H19 -> -24 | O19: =IF(I19=L19,0,31-H19) -> 2 | P19: =IF(I19=L19,0,K19-1) -> 4 | Q19: КЛУБ МАГЕЛАН - ООД | R19: ROOM-SEA | S19: 2 | T19: 2 | U19: =SUMIFS(Magelan!L:L,Magelan!D:D,'Резервации 2026'!E19) -> 2166.6294 | V19: =+U19/M19 -> 361.10489 | W19: Romania | X19: 21 Jan 2026 16:52 | Y19: 21 Jan 2026 | Z19: =MID(X19,4,3) -> Jan | AA19: =IF($I19=AA$1,IF($L19=AA$1,$M19,$O19),IF($L19=AA$1,$P19,0)) -> 0 | AB19: =IF($I19=AB$1,IF($L19=AB$1,$M19,$O19),IF($L19=AB$1,$P19,0)) -> 2 | AC19: =IF($I19=AC$1,IF($L19=AC$1,$M19,$O19),IF($L19=AC$1,$P19,0)) -> 4 | AD19: =IF($I19=AD$1,IF($L19=AD$1,$M19,$O19),IF($L19=AD$1,$P19,0)) -> 0 | AE19: =IF($I19=AE$1,IF($L19=AE$1,$M19,$O19),IF($L19=AE$1,$P19,0)) -> 0 | AF19: =SUM(AA19:AE19) -> 6 | AG19: =+AF19-M19 -> 0 | AH19: =LEFT(X19,2)&"."&VLOOKUP(MID(X19,4,3),'Data validation'!$A$1:$B$12,2,FALSE)&".2025" -> 21.01.2025 | AI19: =WEEKNUM(AH19) -> 4 | AJ19: =H19&"."&VLOOKUP(I19,'Data validation'!$A$1:$B$12,2,FALSE)&".2026" -> 29.06.2026 | AK19: =WEEKNUM(AJ19) -> 27 | AL19: =VLOOKUP(E19,[2]Sheet1!$A:$B,2,FALSE) -> #N/A
A20: =VLOOKUP(Q20,'Data validation'!$K$2:$L$50,2,FALSE) -> TO | B20: =AA20+IF(I20="Jun",IF(_xlfn.NUMBERVALUE(H20)>14,0,IF(_xlfn.NUMBERVALUE(K20)<14,M20,15-_xlfn.NUMBERVALUE(H20))),0) -> 0 | C20: =M20-B20-D20 -> 0 | D20: =IF(L20="Jul",IF(_xlfn.NUMBERVALUE(K20)<11,0,IF(I20="Jul",IF(_xlfn.NUMBERVALUE(H20)>11,M20,_xlfn.NUMBERVALUE(K20)-11),0)),0)+IF(L20="Aug",IF(_xlfn.NUMBERVALUE(K20)>24,IF(_xlfn.NUMBERVALUE(H20)>24,0,25-_xlfn.NUMBERVALUE(H20)),IF(I20="Aug",M20,_xlfn.NUMBERVALUE(K20)-1+32-_xlfn.NUMBERVALUE(H20))),0) -> 7 | E20: 9632 | F20: 2321410 | G20: 20 Jul 2026 | H20: =LEFT(G20,2) -> 20 | I20: =MID(G20,4,3) -> Jul | J20: 27 Jul 2026 | K20: =LEFT(J20,2) -> 27 | L20: =MID(J20,4,3) -> Jul | M20: 7 | N20: =+K20-H20 -> 7 | O20: =IF(I20=L20,0,31-H20) -> 0 | P20: =IF(I20=L20,0,K20-1) -> 0 | Q20: ТУРИСТИЧЕСКА АГЕНЦИЯ СОЛВЕКС - ЕООД | R20: ROOM-SEA | S20: 2 | T20: 0 | U20: =SUMIFS(Solvex!L:L,Solvex!D:D,'Резервации 2026'!E20) -> 2233.2449 | V20: =+U20/M20 -> 319.03499 | W20: Romania | X20: 21 Jan 2026 16:52 | Y20: 21 Jan 2026 | Z20: =MID(X20,4,3) -> Jan | AA20: =IF($I20=AA$1,IF($L20=AA$1,$M20,$O20),IF($L20=AA$1,$P20,0)) -> 0 | AB20: =IF($I20=AB$1,IF($L20=AB$1,$M20,$O20),IF($L20=AB$1,$P20,0)) -> 0 | AC20: =IF($I20=AC$1,IF($L20=AC$1,$M20,$O20),IF($L20=AC$1,$P20,0)) -> 7 | AD20: =IF($I20=AD$1,IF($L20=AD$1,$M20,$O20),IF($L20=AD$1,$P20,0)) -> 0 | AE20: =IF($I20=AE$1,IF($L20=AE$1,$M20,$O20),IF($L20=AE$1,$P20,0)) -> 0 | AF20: =SUM(AA20:AE20) -> 7 | AG20: =+AF20-M20 -> 0 | AH20: =LEFT(X20,2)&"."&VLOOKUP(MID(X20,4,3),'Data validation'!$A$1:$B$12,2,FALSE)&".2025" -> 21.01.2025 | AI20: =WEEKNUM(AH20) -> 4 | AJ20: =H20&"."&VLOOKUP(I20,'Data validation'!$A$1:$B$12,2,FALSE)&".2026" -> 20.07.2026 | AK20: =WEEKNUM(AJ20) -> 30 | AL20: =VLOOKUP(E20,[2]Sheet1!$A:$B,2,FALSE) -> #N/A
A21: =VLOOKUP(Q21,'Data validation'!$K$2:$L$50,2,FALSE) -> TO | B21: =AA21+IF(I21="Jun",IF(_xlfn.NUMBERVALUE(H21)>14,0,IF(_xlfn.NUMBERVALUE(K21)<14,M21,15-_xlfn.NUMBERVALUE(H21))),0) -> 0 | C21: =M21-B21-D21 -> 0 | D21: =IF(L21="Jul",IF(_xlfn.NUMBERVALUE(K21)<11,0,IF(I21="Jul",IF(_xlfn.NUMBERVALUE(H21)>11,M21,_xlfn.NUMBERVALUE(K21)-11),0)),0)+IF(L21="Aug",IF(_xlfn.NUMBERVALUE(K21)>24,IF(_xlfn.NUMBERVALUE(H21)>24,0,25-_xlfn.NUMBERVALUE(H21)),IF(I21="Aug",M21,_xlfn.NUMBERVALUE(K21)-1+32-_xlfn.NUMBERVALUE(H21))),0) -> 6 | E21: 9633 | F21: 0296 | G21: 08 Aug 2026 | H21: =LEFT(G21,2) -> 08 | I21: =MID(G21,4,3) -> Aug | J21: 14 Aug 2026 | K21: =LEFT(J21,2) -> 14 | L21: =MID(J21,4,3) -> Aug | M21: 6 | N21: =+K21-H21 -> 6 | O21: =IF(I21=L21,0,31-H21) -> 0 | P21: =IF(I21=L21,0,K21-1) -> 0 | Q21: АВАТАР ТУР - ООД | R21: ROOM | S21: 1 | T21: 0 | U21: =SUMIFS(Avatar!L:L,Avatar!D:D,'Резервации 2026'!E21) -> 1308.3329 | V21: =+U21/M21 -> 218.05549 | W21: Romania | X21: 21 Jan 2026 17:20 | Y21: 21 Jan 2026 | Z21: =MID(X21,4,3) -> Jan | AA21: =IF($I21=AA$1,IF($L21=AA$1,$M21,$O21),IF($L21=AA$1,$P21,0)) -> 0 | AB21: =IF($I21=AB$1,IF($L21=AB$1,$M21,$O21),IF($L21=AB$1,$P21,0)) -> 0 | AC21: =IF($I21=AC$1,IF($L21=AC$1,$M21,$O21),IF($L21=AC$1,$P21,0)) -> 0 | AD21: =IF($I21=AD$1,IF($L21=AD$1,$M21,$O21),IF($L21=AD$1,$P21,0)) -> 6 | AE21: =IF($I21=AE$1,IF($L21=AE$1,$M21,$O21),IF($L21=AE$1,$P21,0)) -> 0 | AF21: =SUM(AA21:AE21) -> 6 | AG21: =+AF21-M21 -> 0 | AH21: =LEFT(X21,2)&"."&VLOOKUP(MID(X21,4,3),'Data validation'!$A$1:$B$12,2,FALSE)&".2025" -> 21.01.2025 | AI21: =WEEKNUM(AH21) -> 4 | AJ21: =H21&"."&VLOOKUP(I21,'Data validation'!$A$1:$B$12,2,FALSE)&".2026" -> 08.08.2026 | AK21: =WEEKNUM(AJ21) -> 32 | AL21: =VLOOKUP(E21,[2]Sheet1!$A:$B,2,FALSE) -> #N/A
A22: =VLOOKUP(Q22,'Data validation'!$K$2:$L$50,2,FALSE) -> TO | B22: =AA22+IF(I22="Jun",IF(_xlfn.NUMBERVALUE(H22)>14,0,IF(_xlfn.NUMBERVALUE(K22)<14,M22,15-_xlfn.NUMBERVALUE(H22))),0) -> 0 | C22: =M22-B22-D22 -> 0 | D22: =IF(L22="Jul",IF(_xlfn.NUMBERVALUE(K22)<11,0,IF(I22="Jul",IF(_xlfn.NUMBERVALUE(H22)>11,M22,_xlfn.NUMBERVALUE(K22)-11),0)),0)+IF(L22="Aug",IF(_xlfn.NUMBERVALUE(K22)>24,IF(_xlfn.NUMBERVALUE(H22)>24,0,25-_xlfn.NUMBERVALUE(H22)),IF(I22="Aug",M22,_xlfn.NUMBERVALUE(K22)-1+32-_xlfn.NUMBERVALUE(H22))),0) -> 7 | E22: 9634 | F22: 2321420 | G22: 20 Jul 2026 | H22: =LEFT(G22,2) -> 20 | I22: =MID(G22,4,3) -> Jul | J22: 27 Jul 2026 | K22: =LEFT(J22,2) -> 27 | L22: =MID(J22,4,3) -> Jul | M22: 7 | N22: =+K22-H22 -> 7 | O22: =IF(I22=L22,0,31-H22) -> 0 | P22: =IF(I22=L22,0,K22-1) -> 0 | Q22: ТУРИСТИЧЕСКА АГЕНЦИЯ СОЛВЕКС - ЕООД | R22: APP1-SEA | S22: 3 | T22: 0 | U22: =SUMIFS(Solvex!L:L,Solvex!D:D,'Резервации 2026'!E22) -> 3323.581 | V22: =+U22/M22 -> 474.79729 | W22: Romania | X22: 21 Jan 2026 17:21 | Y22: 21 Jan 2026 | Z22: =MID(X22,4,3) -> Jan | AA22: =IF($I22=AA$1,IF($L22=AA$1,$M22,$O22),IF($L22=AA$1,$P22,0)) -> 0 | AB22: =IF($I22=AB$1,IF($L22=AB$1,$M22,$O22),IF($L22=AB$1,$P22,0)) -> 0 | AC22: =IF($I22=AC$1,IF($L22=AC$1,$M22,$O22),IF($L22=AC$1,$P22,0)) -> 7 | AD22: =IF($I22=AD$1,IF($L22=AD$1,$M22,$O22),IF($L22=AD$1,$P22,0)) -> 0 | AE22: =IF($I22=AE$1,IF($L22=AE$1,$M22,$O22),IF($L22=AE$1,$P22,0)) -> 0 | AF22: =SUM(AA22:AE22) -> 7 | AG22: =+AF22-M22 -> 0 | AH22: =LEFT(X22,2)&"."&VLOOKUP(MID(X22,4,3),'Data validation'!$A$1:$B$12,2,FALSE)&".2025" -> 21.01.2025 | AI22: =WEEKNUM(AH22) -> 4 | AJ22: =H22&"."&VLOOKUP(I22,'Data validation'!$A$1:$B$12,2,FALSE)&".2026" -> 20.07.2026 | AK22: =WEEKNUM(AJ22) -> 30 | AL22: =VLOOKUP(E22,[2]Sheet1!$A:$B,2,FALSE) -> #N/A
A23: =VLOOKUP(Q23,'Data validation'!$K$2:$L$50,2,FALSE) -> BOOKING | B23: =AA23+IF(I23="Jun",IF(_xlfn.NUMBERVALUE(H23)>14,0,IF(_xlfn.NUMBERVALUE(K23)<14,M23,15-_xlfn.NUMBERVALUE(H23))),0) -> 1 | C23: =M23-B23-D23 -> 1 | D23: =IF(L23="Jul",IF(_xlfn.NUMBERVALUE(K23)<11,0,IF(I23="Jul",IF(_xlfn.NUMBERVALUE(H23)>11,M23,_xlfn.NUMBERVALUE(K23)-11),0)),0)+IF(L23="Aug",IF(_xlfn.NUMBERVALUE(K23)>24,IF(_xlfn.NUMBERVALUE(H23)>24,0,25-_xlfn.NUMBERVALUE(H23)),IF(I23="Aug",M23,_xlfn.NUMBERVALUE(K23)-1+32-_xlfn.NUMBERVALUE(H23))),0) -> 0 | E23: 10335 | F23: 6392823479 | G23: 30 May 2026 | H23: =LEFT(G23,2) -> 30 | I23: =MID(G23,4,3) -> May | J23: 01 Jun 2026 | K23: =LEFT(J23,2) -> 01 | L23: =MID(J23,4,3) -> Jun | M23: 2 | N23: =+K23-H23 -> -29 | O23: =IF(I23=L23,0,31-H23) -> 1 | P23: =IF(I23=L23,0,K23-1) -> 0 | Q23: BOOKING | R23: APP1-POOL | S23: 2 | T23: 1 | U23: 694.5888 | V23: 347.2944 | W23: Romania | X23: 05 Mar 2026 09:32 | Y23: 05 Mar 2026 | Z23: =MID(X23,4,3) -> Mar | AA23: =IF($I23=AA$1,IF($L23=AA$1,$M23,$O23),IF($L23=AA$1,$P23,0)) -> 1 | AB23: =IF($I23=AB$1,IF($L23=AB$1,$M23,$O23),IF($L23=AB$1,$P23,0)) -> 0 | AC23: =IF($I23=AC$1,IF($L23=AC$1,$M23,$O23),IF($L23=AC$1,$P23,0)) -> 0 | AD23: =IF($I23=AD$1,IF($L23=AD$1,$M23,$O23),IF($L23=AD$1,$P23,0)) -> 0 | AE23: =IF($I23=AE$1,IF($L23=AE$1,$M23,$O23),IF($L23=AE$1,$P23,0)) -> 0 | AF23: =SUM(AA23:AE23) -> 1 | AG23: =+AF23-M23 -> -1 | AH23: =LEFT(X23,2)&"."&VLOOKUP(MID(X23,4,3),'Data validation'!$A$1:$B$12,2,FALSE)&".2025" -> 05.03.2025 | AI23: =WEEKNUM(AH23) -> 10 | AJ23: =H23&"."&VLOOKUP(I23,'Data validation'!$A$1:$B$12,2,FALSE)&".2026" -> 30.05.2026 | AK23: =WEEKNUM(AJ23) -> 22 | AL23: =VLOOKUP(E23,[2]Sheet1!$A:$B,2,FALSE) -> Анулирана
A24: =VLOOKUP(Q24,'Data validation'!$K$2:$L$50,2,FALSE) -> TO | B24: =AA24+IF(I24="Jun",IF(_xlfn.NUMBERVALUE(H24)>14,0,IF(_xlfn.NUMBERVALUE(K24)<14,M24,15-_xlfn.NUMBERVALUE(H24))),0) -> 0 | C24: =M24-B24-D24 -> 0 | D24: =IF(L24="Jul",IF(_xlfn.NUMBERVALUE(K24)<11,0,IF(I24="Jul",IF(_xlfn.NUMBERVALUE(H24)>11,M24,_xlfn.NUMBERVALUE(K24)-11),0)),0)+IF(L24="Aug",IF(_xlfn.NUMBERVALUE(K24)>24,IF(_xlfn.NUMBERVALUE(H24)>24,0,25-_xlfn.NUMBERVALUE(H24)),IF(I24="Aug",M24,_xlfn.NUMBERVALUE(K24)-1+32-_xlfn.NUMBERVALUE(H24))),0) -> 5 | E24: 10245 | F24: 1247335.196050 | G24: 17 Aug 2026 | H24: =LEFT(G24,2) -> 17 | I24: =MID(G24,4,3) -> Aug | J24: 22 Aug 2026 | K24: =LEFT(J24,2) -> 22 | L24: =MID(J24,4,3) -> Aug | M24: 5 | N24: =+K24-H24 -> 5 | O24: =IF(I24=L24,0,31-H24) -> 0 | P24: =IF(I24=L24,0,K24-1) -> 0 | Q24: СЛР-ХОЛИДЕЙ-СЪРВИС ЕООД | R24: APP1-POOL | S24: 2 | T24: 1 | U24: =SUMIFS(SLR!L:L,SLR!D:D,'Резервации 2026'!E24) -> 1709.1998 | V24: =+U24/M24 -> 341.83997 | W24: Romania | X24: 27 Feb 2026 09:50 | Y24: 26 Feb 2026 | Z24: =MID(X24,4,3) -> Feb | AA24: =IF($I24=AA$1,IF($L24=AA$1,$M24,$O24),IF($L24=AA$1,$P24,0)) -> 0 | AB24: =IF($I24=AB$1,IF($L24=AB$1,$M24,$O24),IF($L24=AB$1,$P24,0)) -> 0 | AC24: =IF($I24=AC$1,IF($L24=AC$1,$M24,$O24),IF($L24=AC$1,$P24,0)) -> 0 | AD24: =IF($I24=AD$1,IF($L24=AD$1,$M24,$O24),IF($L24=AD$1,$P24,0)) -> 5 | AE24: =IF($I24=AE$1,IF($L24=AE$1,$M24,$O24),IF($L24=AE$1,$P24,0)) -> 0 | AF24: =SUM(AA24:AE24) -> 5 | AG24: =+AF24-M24 -> 0 | AH24: =LEFT(X24,2)&"."&VLOOKUP(MID(X24,4,3),'Data validation'!$A$1:$B$12,2,FALSE)&".2025" -> 27.02.2025 | AI24: =WEEKNUM(AH24) -> 9 | AJ24: =H24&"."&VLOOKUP(I24,'Data validation'!$A$1:$B$12,2,FALSE)&".2026" -> 17.08.2026 | AK24: =WEEKNUM(AJ24) -> 34 | AL24: =VLOOKUP(E24,[2]Sheet1!$A:$B,2,FALSE) -> #N/A
A25: =VLOOKUP(Q25,'Data validation'!$K$2:$L$50,2,FALSE) -> TOPOLA SKIES | B25: =AA25+IF(I25="Jun",IF(_xlfn.NUMBERVALUE(H25)>14,0,IF(_xlfn.NUMBERVALUE(K25)<14,M25,15-_xlfn.NUMBERVALUE(H25))),0) -> 2 | C25: =M25-B25-D25 -> 0 | D25: =IF(L25="Jul",IF(_xlfn.NUMBERVALUE(K25)<11,0,IF(I25="Jul",IF(_xlfn.NUMBERVALUE(H25)>11,M25,_xlfn.NUMBERVALUE(K25)-11),0)),0)+IF(L25="Aug",IF(_xlfn.NUMBERVALUE(K25)>24,IF(_xlfn.NUMBERVALUE(H25)>24,0,25-_xlfn.NUMBERVALUE(H25)),IF(I25="Aug",M25,_xlfn.NUMBERVALUE(K25)-1+32-_xlfn.NUMBERVALUE(H25))),0) -> 0 | E25: 10336 | F25: 487092 | G25: 23 May 2026 | H25: =LEFT(G25,2) -> 23 | I25: =MID(G25,4,3) -> May | J25: 25 May 2026 | K25: =LEFT(J25,2) -> 25 | L25: =MID(J25,4,3) -> May | M25: 2 | N25: =+K25-H25 -> 2 | O25: =IF(I25=L25,0,31-H25) -> 0 | P25: =IF(I25=L25,0,K25-1) -> 0 | Q25: TOPOLA SKIES | R25: APP1-POOL | S25: 3 | T25: 1 | U25: 740.99042 | V25: 370.49521 | X25: 05 Mar 2026 10:03 | Y25: 05 Mar 2026 | Z25: =MID(X25,4,3) -> Mar | AA25: =IF($I25=AA$1,IF($L25=AA$1,$M25,$O25),IF($L25=AA$1,$P25,0)) -> 2 | AB25: =IF($I25=AB$1,IF($L25=AB$1,$M25,$O25),IF($L25=AB$1,$P25,0)) -> 0 | AC25: =IF($I25=AC$1,IF($L25=AC$1,$M25,$O25),IF($L25=AC$1,$P25,0)) -> 0 | AD25: =IF($I25=AD$1,IF($L25=AD$1,$M25,$O25),IF($L25=AD$1,$P25,0)) -> 0 | AE25: =IF($I25=AE$1,IF($L25=AE$1,$M25,$O25),IF($L25=AE$1,$P25,0)) -> 0 | AF25: =SUM(AA25:AE25) -> 2 | AG25: =+AF25-M25 -> 0 | AH25: =LEFT(X25,2)&"."&VLOOKUP(MID(X25,4,3),'Data validation'!$A$1:$B$12,2,FALSE)&".2025" -> 05.03.2025 | AI25: =WEEKNUM(AH25) -> 10 | AJ25: =H25&"."&VLOOKUP(I25,'Data validation'!$A$1:$B$12,2,FALSE)&".2026" -> 23.05.2026 | AK25: =WEEKNUM(AJ25) -> 21 | AL25: =VLOOKUP(E25,[2]Sheet1!$A:$B,2,FALSE) -> Анулирана
A26: =VLOOKUP(Q26,'Data validation'!$K$2:$L$50,2,FALSE) -> TO | B26: =AA26+IF(I26="Jun",IF(_xlfn.NUMBERVALUE(H26)>14,0,IF(_xlfn.NUMBERVALUE(K26)<14,M26,15-_xlfn.NUMBERVALUE(H26))),0) -> 0 | C26: =M26-B26-D26 -> 0 | D26: =IF(L26="Jul",IF(_xlfn.NUMBERVALUE(K26)<11,0,IF(I26="Jul",IF(_xlfn.NUMBERVALUE(H26)>11,M26,_xlfn.NUMBERVALUE(K26)-11),0)),0)+IF(L26="Aug",IF(_xlfn.NUMBERVALUE(K26)>24,IF(_xlfn.NUMBERVALUE(H26)>24,0,25-_xlfn.NUMBERVALUE(H26)),IF(I26="Aug",M26,_xlfn.NUMBERVALUE(K26)-1+32-_xlfn.NUMBERVALUE(H26))),0) -> 7 | E26: 10246 | F26: 1247390.196053 | G26: 12 Jul 2026 | H26: =LEFT(G26,2) -> 12 | I26: =MID(G26,4,3) -> Jul | J26: 19 Jul 2026 | K26: =LEFT(J26,2) -> 19 | L26: =MID(J26,4,3) -> Jul | M26: 7 | N26: =+K26-H26 -> 7 | O26: =IF(I26=L26,0,31-H26) -> 0 | P26: =IF(I26=L26,0,K26-1) -> 0 | Q26: СЛР-ХОЛИДЕЙ-СЪРВИС ЕООД | R26: APP1-POOL | S26: 3 | T26: 1 | U26: =SUMIFS(SLR!L:L,SLR!D:D,'Резервации 2026'!E26) -> 3230.3466 | V26: =+U26/M26 -> 461.47809 | W26: Romania | X26: 27 Feb 2026 09:56 | Y26: 27 Feb 2026 | Z26: =MID(X26,4,3) -> Feb | AA26: =IF($I26=AA$1,IF($L26=AA$1,$M26,$O26),IF($L26=AA$1,$P26,0)) -> 0 | AB26: =IF($I26=AB$1,IF($L26=AB$1,$M26,$O26),IF($L26=AB$1,$P26,0)) -> 0 | AC26: =IF($I26=AC$1,IF($L26=AC$1,$M26,$O26),IF($L26=AC$1,$P26,0)) -> 7 | AD26: =IF($I26=AD$1,IF($L26=AD$1,$M26,$O26),IF($L26=AD$1,$P26,0)) -> 0 | AE26: =IF($I26=AE$1,IF($L26=AE$1,$M26,$O26),IF($L26=AE$1,$P26,0)) -> 0 | AF26: =SUM(AA26:AE26) -> 7 | AG26: =+AF26-M26 -> 0 | AH26: =LEFT(X26,2)&"."&VLOOKUP(MID(X26,4,3),'Data validation'!$A$1:$B$12,2,FALSE)&".2025" -> 27.02.2025 | AI26: =WEEKNUM(AH26) -> 9 | AJ26: =H26&"."&VLOOKUP(I26,'Data validation'!$A$1:$B$12,2,FALSE)&".2026" -> 12.07.2026 | AK26: =WEEKNUM(AJ26) -> 29 | AL26: =VLOOKUP(E26,[2]Sheet1!$A:$B,2,FALSE) -> #N/A
A27: =VLOOKUP(Q27,'Data validation'!$K$2:$L$50,2,FALSE) -> TO | B27: =AA27+IF(I27="Jun",IF(_xlfn.NUMBERVALUE(H27)>14,0,IF(_xlfn.NUMBERVALUE(K27)<14,M27,15-_xlfn.NUMBERVALUE(H27))),0) -> 0 | C27: =M27-B27-D27 -> 4 | D27: =IF(L27="Jul",IF(_xlfn.NUMBERVALUE(K27)<11,0,IF(I27="Jul",IF(_xlfn.NUMBERVALUE(H27)>11,M27,_xlfn.NUMBERVALUE(K27)-11),0)),0)+IF(L27="Aug",IF(_xlfn.NUMBERVALUE(K27)>24,IF(_xlfn.NUMBERVALUE(H27)>24,0,25-_xlfn.NUMBERVALUE(H27)),IF(I27="Aug",M27,_xlfn.NUMBERVALUE(K27)-1+32-_xlfn.NUMBERVALUE(H27))),0) -> 0 | E27: 10337 | F27: 1248678.196840 | G27: 22 Jun 2026 | H27: =LEFT(G27,2) -> 22 | I27: =MID(G27,4,3) -> Jun | J27: 26 Jun 2026 | K27: =LEFT(J27,2) -> 26 | L27: =MID(J27,4,3) -> Jun | M27: 4 | N27: =+K27-H27 -> 4 | O27: =IF(I27=L27,0,31-H27) -> 0 | P27: =IF(I27=L27,0,K27-1) -> 0 | Q27: СЛР-ХОЛИДЕЙ-СЪРВИС ЕООД | R27: APP1-POOL | S27: 2 | T27: 2 | U27: =SUMIFS(SLR!L:L,SLR!D:D,'Резервации 2026'!E27) -> 1875.0542 | V27: =+U27/M27 -> 468.76356 | W27: Romania | X27: 05 Mar 2026 10:09 | Y27: 05 Mar 2026 | Z27: =MID(X27,4,3) -> Mar | AA27: =IF($I27=AA$1,IF($L27=AA$1,$M27,$O27),IF($L27=AA$1,$P27,0)) -> 0 | AB27: =IF($I27=AB$1,IF($L27=AB$1,$M27,$O27),IF($L27=AB$1,$P27,0)) -> 4 | AC27: =IF($I27=AC$1,IF($L27=AC$1,$M27,$O27),IF($L27=AC$1,$P27,0)) -> 0 | AD27: =IF($I27=AD$1,IF($L27=AD$1,$M27,$O27),IF($L27=AD$1,$P27,0)) -> 0 | AE27: =IF($I27=AE$1,IF($L27=AE$1,$M27,$O27),IF($L27=AE$1,$P27,0)) -> 0 | AF27: =SUM(AA27:AE27) -> 4 | AG27: =+AF27-M27 -> 0 | AH27: =LEFT(X27,2)&"."&VLOOKUP(MID(X27,4,3),'Data validation'!$A$1:$B$12,2,FALSE)&".2025" -> 05.03.2025 | AI27: =WEEKNUM(AH27) -> 10 | AJ27: =H27&"."&VLOOKUP(I27,'Data validation'!$A$1:$B$12,2,FALSE)&".2026" -> 22.06.2026 | AK27: =WEEKNUM(AJ27) -> 26 | AL27: =VLOOKUP(E27,[2]Sheet1!$A:$B,2,FALSE) -> #N/A
A28: =VLOOKUP(Q28,'Data validation'!$K$2:$L$50,2,FALSE) -> TO | B28: =AA28+IF(I28="Jun",IF(_xlfn.NUMBERVALUE(H28)>14,0,IF(_xlfn.NUMBERVALUE(K28)<14,M28,15-_xlfn.NUMBERVALUE(H28))),0) -> 0 | C28: =M28-B28-D28 -> 0 | D28: =IF(L28="Jul",IF(_xlfn.NUMBERVALUE(K28)<11,0,IF(I28="Jul",IF(_xlfn.NUMBERVALUE(H28)>11,M28,_xlfn.NUMBERVALUE(K28)-11),0)),0)+IF(L28="Aug",IF(_xlfn.NUMBERVALUE(K28)>24,IF(_xlfn.NUMBERVALUE(H28)>24,0,25-_xlfn.NUMBERVALUE(H28)),IF(I28="Aug",M28,_xlfn.NUMBERVALUE(K28)-1+32-_xlfn.NUMBERVALUE(H28))),0) -> 5 | E28: 10247 | F28: 1247362.196067 | G28: 13 Jul 2026 | H28: =LEFT(G28,2) -> 13 | I28: =MID(G28,4,3) -> Jul | J28: 18 Jul 2026 | K28: =LEFT(J28,2) -> 18 | L28: =MID(J28,4,3) -> Jul | M28: 5 | N28: =+K28-H28 -> 5 | O28: =IF(I28=L28,0,31-H28) -> 0 | P28: =IF(I28=L28,0,K28-1) -> 0 | Q28: СЛР-ХОЛИДЕЙ-СЪРВИС ЕООД | R28: APP1-DELUXE | S28: 2 | T28: 2 | U28: =SUMIFS(SLR!L:L,SLR!D:D,'Резервации 2026'!E28) -> 2422.2955 | V28: =+U28/M28 -> 484.45909 | W28: Romania | X28: 27 Feb 2026 10:02 | Y28: 26 Feb 2026 | Z28: =MID(X28,4,3) -> Feb | AA28: =IF($I28=AA$1,IF($L28=AA$1,$M28,$O28),IF($L28=AA$1,$P28,0)) -> 0 | AB28: =IF($I28=AB$1,IF($L28=AB$1,$M28,$O28),IF($L28=AB$1,$P28,0)) -> 0 | AC28: =IF($I28=AC$1,IF($L28=AC$1,$M28,$O28),IF($L28=AC$1,$P28,0)) -> 5 | AD28: =IF($I28=AD$1,IF($L28=AD$1,$M28,$O28),IF($L28=AD$1,$P28,0)) -> 0 | AE28: =IF($I28=AE$1,IF($L28=AE$1,$M28,$O28),IF($L28=AE$1,$P28,0)) -> 0 | AF28: =SUM(AA28:AE28) -> 5 | AG28: =+AF28-M28 -> 0 | AH28: =LEFT(X28,2)&"."&VLOOKUP(MID(X28,4,3),'Data validation'!$A$1:$B$12,2,FALSE)&".2025" -> 27.02.2025 | AI28: =WEEKNUM(AH28) -> 9 | AJ28: =H28&"."&VLOOKUP(I28,'Data validation'!$A$1:$B$12,2,FALSE)&".2026" -> 13.07.2026 | AK28: =WEEKNUM(AJ28) -> 29 | AL28: =VLOOKUP(E28,[2]Sheet1!$A:$B,2,FALSE) -> #N/A
A29: =VLOOKUP(Q29,'Data validation'!$K$2:$L$50,2,FALSE) -> TO | B29: =AA29+IF(I29="Jun",IF(_xlfn.NUMBERVALUE(H29)>14,0,IF(_xlfn.NUMBERVALUE(K29)<14,M29,15-_xlfn.NUMBERVALUE(H29))),0) -> 0 | C29: =M29-B29-D29 -> 6 | D29: =IF(L29="Jul",IF(_xlfn.NUMBERVALUE(K29)<11,0,IF(I29="Jul",IF(_xlfn.NUMBERVALUE(H29)>11,M29,_xlfn.NUMBERVALUE(K29)-11),0)),0)+IF(L29="Aug",IF(_xlfn.NUMBERVALUE(K29)>24,IF(_xlfn.NUMBERVALUE(H29)>24,0,25-_xlfn.NUMBERVALUE(H29)),IF(I29="Aug",M29,_xlfn.NUMBERVALUE(K29)-1+32-_xlfn.NUMBERVALUE(H29))),0) -> 0 | E29: 10086 | F29: 2327451 | G29: 05 Jul 2026 | H29: =LEFT(G29,2) -> 05 | I29: =MID(G29,4,3) -> Jul | J29: 11 Jul 2026 | K29: =LEFT(J29,2) -> 11 | L29: =MID(J29,4,3) -> Jul | M29: 6 | N29: =+K29-H29 -> 6 | O29: =IF(I29=L29,0,31-H29) -> 0 | P29: =IF(I29=L29,0,K29-1) -> 0 | Q29: ТУРИСТИЧЕСКА АГЕНЦИЯ СОЛВЕКС - ЕООД | R29: ROOM-SEA | S29: 2 | T29: 2 | U29: =SUMIFS(Solvex!L:L,Solvex!D:D,'Резервации 2026'!E29) -> 2402.1895 | V29: =+U29/M29 -> 400.36492 | W29: Romania | X29: 15 Feb 2026 12:08 | Y29: 14 Feb 2026 | Z29: =MID(X29,4,3) -> Feb | AA29: =IF($I29=AA$1,IF($L29=AA$1,$M29,$O29),IF($L29=AA$1,$P29,0)) -> 0 | AB29: =IF($I29=AB$1,IF($L29=AB$1,$M29,$O29),IF($L29=AB$1,$P29,0)) -> 0 | AC29: =IF($I29=AC$1,IF($L29=AC$1,$M29,$O29),IF($L29=AC$1,$P29,0)) -> 6 | AD29: =IF($I29=AD$1,IF($L29=AD$1,$M29,$O29),IF($L29=AD$1,$P29,0)) -> 0 | AE29: =IF($I29=AE$1,IF($L29=AE$1,$M29,$O29),IF($L29=AE$1,$P29,0)) -> 0 | AF29: =SUM(AA29:AE29) -> 6 | AG29: =+AF29-M29 -> 0 | AH29: =LEFT(X29,2)&"."&VLOOKUP(MID(X29,4,3),'Data validation'!$A$1:$B$12,2,FALSE)&".2025" -> 15.02.2025 | AI29: =WEEKNUM(AH29) -> 7 | AJ29: =H29&"."&VLOOKUP(I29,'Data validation'!$A$1:$B$12,2,FALSE)&".2026" -> 05.07.2026 | AK29: =WEEKNUM(AJ29) -> 28 | AL29: =VLOOKUP(E29,[2]Sheet1!$A:$B,2,FALSE) -> #N/A
A30: =VLOOKUP(Q30,'Data validation'!$K$2:$L$50,2,FALSE) -> TO | B30: =AA30+IF(I30="Jun",IF(_xlfn.NUMBERVALUE(H30)>14,0,IF(_xlfn.NUMBERVALUE(K30)<14,M30,15-_xlfn.NUMBERVALUE(H30))),0) -> 0 | C30: =M30-B30-D30 -> 0 | D30: =IF(L30="Jul",IF(_xlfn.NUMBERVALUE(K30)<11,0,IF(I30="Jul",IF(_xlfn.NUMBERVALUE(H30)>11,M30,_xlfn.NUMBERVALUE(K30)-11),0)),0)+IF(L30="Aug",IF(_xlfn.NUMBERVALUE(K30)>24,IF(_xlfn.NUMBERVALUE(H30)>24,0,25-_xlfn.NUMBERVALUE(H30)),IF(I30="Aug",M30,_xlfn.NUMBERVALUE(K30)-1+32-_xlfn.NUMBERVALUE(H30))),0) -> 7 | E30: 9635 | F30: 2321426 | G30: 20 Jul 2026 | H30: =LEFT(G30,2) -> 20 | I30: =MID(G30,4,3) -> Jul | J30: 27 Jul 2026 | K30: =LEFT(J30,2) -> 27 | L30: =MID(J30,4,3) -> Jul | M30: 7 | N30: =+K30-H30 -> 7 | O30: =IF(I30=L30,0,31-H30) -> 0 | P30: =IF(I30=L30,0,K30-1) -> 0 | Q30: ТУРИСТИЧЕСКА АГЕНЦИЯ СОЛВЕКС - ЕООД | R30: APP1-SEA | S30: 3 | T30: 1 | U30: =SUMIFS(Solvex!L:L,Solvex!D:D,'Резервации 2026'!E30) -> 3323.581 | V30: =+U30/M30 -> 474.79729 | W30: Romania | X30: 21 Jan 2026 17:48 | Y30: 21 Jan 2026 | Z30: =MID(X30,4,3) -> Jan | AA30: =IF($I30=AA$1,IF($L30=AA$1,$M30,$O30),IF($L30=AA$1,$P30,0)) -> 0 | AB30: =IF($I30=AB$1,IF($L30=AB$1,$M30,$O30),IF($L30=AB$1,$P30,0)) -> 0 | AC30: =IF($I30=AC$1,IF($L30=AC$1,$M30,$O30),IF($L30=AC$1,$P30,0)) -> 7 | AD30: =IF($I30=AD$1,IF($L30=AD$1,$M30,$O30),IF($L30=AD$1,$P30,0)) -> 0 | AE30: =IF($I30=AE$1,IF($L30=AE$1,$M30,$O30),IF($L30=AE$1,$P30,0)) -> 0 | AF30: =SUM(AA30:AE30) -> 7 | AG30: =+AF30-M30 -> 0 | AH30: =LEFT(X30,2)&"."&VLOOKUP(MID(X30,4,3),'Data validation'!$A$1:$B$12,2,FALSE)&".2025" -> 21.01.2025 | AI30: =WEEKNUM(AH30) -> 4 | AJ30: =H30&"."&VLOOKUP(I30,'Data validation'!$A$1:$B$12,2,FALSE)&".2026" -> 20.07.2026 | AK30: =WEEKNUM(AJ30) -> 30 | AL30: =VLOOKUP(E30,[2]Sheet1!$A:$B,2,FALSE) -> #N/A
A31: =VLOOKUP(Q31,'Data validation'!$K$2:$L$50,2,FALSE) -> TO | B31: =AA31+IF(I31="Jun",IF(_xlfn.NUMBERVALUE(H31)>14,0,IF(_xlfn.NUMBERVALUE(K31)<14,M31,15-_xlfn.NUMBERVALUE(H31))),0) -> 0 | C31: =M31-B31-D31 -> 0 | D31: =IF(L31="Jul",IF(_xlfn.NUMBERVALUE(K31)<11,0,IF(I31="Jul",IF(_xlfn.NUMBERVALUE(H31)>11,M31,_xlfn.NUMBERVALUE(K31)-11),0)),0)+IF(L31="Aug",IF(_xlfn.NUMBERVALUE(K31)>24,IF(_xlfn.NUMBERVALUE(H31)>24,0,25-_xlfn.NUMBERVALUE(H31)),IF(I31="Aug",M31,_xlfn.NUMBERVALUE(K31)-1+32-_xlfn.NUMBERVALUE(H31))),0) -> 3 | E31: 9776 | F31: 2322977 | G31: 31 Jul 2026 | H31: =LEFT(G31,2) -> 31 | I31: =MID(G31,4,3) -> Jul | J31: 03 Aug 2026 | K31: =LEFT(J31,2) -> 03 | L31: =MID(J31,4,3) -> Aug | M31: 3 | N31: =+K31-H31 -> -28 | O31: =IF(I31=L31,0,31-H31) -> 0 | P31: =IF(I31=L31,0,K31-1) -> 2 | Q31: ТУРИСТИЧЕСКА АГЕНЦИЯ СОЛВЕКС - ЕООД | R31: ROOM | S31: 2 | T31: 2 | U31: =SUMIFS(Solvex!L:L,Solvex!D:D,'Резервации 2026'!E31) -> 1668.7142 | V31: =+U31/M31 -> 556.23805 | W31: Romania | X31: 27 Jan 2026 14:08 | Y31: 27 Jan 2026 | Z31: =MID(X31,4,3) -> Jan | AA31: =IF($I31=AA$1,IF($L31=AA$1,$M31,$O31),IF($L31=AA$1,$P31,0)) -> 0 | AB31: =IF($I31=AB$1,IF($L31=AB$1,$M31,$O31),IF($L31=AB$1,$P31,0)) -> 0 | AC31: =IF($I31=AC$1,IF($L31=AC$1,$M31,$O31),IF($L31=AC$1,$P31,0)) -> 0 | AD31: =IF($I31=AD$1,IF($L31=AD$1,$M31,$O31),IF($L31=AD$1,$P31,0)) -> 2 | AE31: =IF($I31=AE$1,IF($L31=AE$1,$M31,$O31),IF($L31=AE$1,$P31,0)) -> 0 | AF31: =SUM(AA31:AE31) -> 2 | AG31: =+AF31-M31 -> -1 | AH31: =LEFT(X31,2)&"."&VLOOKUP(MID(X31,4,3),'Data validation'!$A$1:$B$12,2,FALSE)&".2025" -> 27.01.2025 | AI31: =WEEKNUM(AH31) -> 5 | AJ31: =H31&"."&VLOOKUP(I31,'Data validation'!$A$1:$B$12,2,FALSE)&".2026" -> 31.07.2026 | AK31: =WEEKNUM(AJ31) -> 31 | AL31: =VLOOKUP(E31,[2]Sheet1!$A:$B,2,FALSE) -> #N/A
A32: =VLOOKUP(Q32,'Data validation'!$K$2:$L$50,2,FALSE) -> TO | B32: =AA32+IF(I32="Jun",IF(_xlfn.NUMBERVALUE(H32)>14,0,IF(_xlfn.NUMBERVALUE(K32)<14,M32,15-_xlfn.NUMBERVALUE(H32))),0) -> 0 | C32: =M32-B32-D32 -> 0 | D32: =IF(L32="Jul",IF(_xlfn.NUMBERVALUE(K32)<11,0,IF(I32="Jul",IF(_xlfn.NUMBERVALUE(H32)>11,M32,_xlfn.NUMBERVALUE(K32)-11),0)),0)+IF(L32="Aug",IF(_xlfn.NUMBERVALUE(K32)>24,IF(_xlfn.NUMBERVALUE(H32)>24,0,25-_xlfn.NUMBERVALUE(H32)),IF(I32="Aug",M32,_xlfn.NUMBERVALUE(K32)-1+32-_xlfn.NUMBERVALUE(H32))),0) -> 7 | E32: 10087 | F32: 5828 | G32: 27 Jul 2026 | H32: =LEFT(G32,2) -> 27 | I32: =MID(G32,4,3) -> Jul | J32: 03 Aug 2026 | K32: =LEFT(J32,2) -> 03 | L32: =MID(J32,4,3) -> Aug | M32: 7 | N32: =+K32-H32 -> -24 | O32: =IF(I32=L32,0,31-H32) -> 4 | P32: =IF(I32=L32,0,K32-1) -> 2 | Q32: ТЕДИ - КАМ - ЕООД | R32: APP1-POOL | S32: 2 | T32: 2 | U32: =SUMIFS(TediKam!L:L,TediKam!D:D,'Резервации 2026'!E32) -> 2991.0313 | V32: =+U32/M32 -> 427.29018 | W32: Israel | X32: 15 Feb 2026 15:27 | Y32: 15 Feb 2026 | Z32: =MID(X32,4,3) -> Feb | AA32: =IF($I32=AA$1,IF($L32=AA$1,$M32,$O32),IF($L32=AA$1,$P32,0)) -> 0 | AB32: =IF($I32=AB$1,IF($L32=AB$1,$M32,$O32),IF($L32=AB$1,$P32,0)) -> 0 | AC32: =IF($I32=AC$1,IF($L32=AC$1,$M32,$O32),IF($L32=AC$1,$P32,0)) -> 4 | AD32: =IF($I32=AD$1,IF($L32=AD$1,$M32,$O32),IF($L32=AD$1,$P32,0)) -> 2 | AE32: =IF($I32=AE$1,IF($L32=AE$1,$M32,$O32),IF($L32=AE$1,$P32,0)) -> 0 | AF32: =SUM(AA32:AE32) -> 6 | AG32: =+AF32-M32 -> -1 | AH32: =LEFT(X32,2)&"."&VLOOKUP(MID(X32,4,3),'Data validation'!$A$1:$B$12,2,FALSE)&".2025" -> 15.02.2025 | AI32: =WEEKNUM(AH32) -> 7 | AJ32: =H32&"."&VLOOKUP(I32,'Data validation'!$A$1:$B$12,2,FALSE)&".2026" -> 27.07.2026 | AK32: =WEEKNUM(AJ32) -> 31 | AL32: =VLOOKUP(E32,[2]Sheet1!$A:$B,2,FALSE) -> #N/A
A33: =VLOOKUP(Q33,'Data validation'!$K$2:$L$50,2,FALSE) -> BOOKING | B33: =AA33+IF(I33="Jun",IF(_xlfn.NUMBERVALUE(H33)>14,0,IF(_xlfn.NUMBERVALUE(K33)<14,M33,15-_xlfn.NUMBERVALUE(H33))),0) -> 1 | C33: =M33-B33-D33 -> 1 | D33: =IF(L33="Jul",IF(_xlfn.NUMBERVALUE(K33)<11,0,IF(I33="Jul",IF(_xlfn.NUMBERVALUE(H33)>11,M33,_xlfn.NUMBERVALUE(K33)-11),0)),0)+IF(L33="Aug",IF(_xlfn.NUMBERVALUE(K33)>24,IF(_xlfn.NUMBERVALUE(H33)>24,0,25-_xlfn.NUMBERVALUE(H33)),IF(I33="Aug",M33,_xlfn.NUMBERVALUE(K33)-1+32-_xlfn.NUMBERVALUE(H33))),0) -> 0 | E33: 10088 | F33: 5979154621 | G33: 30 May 2026 | H33: =LEFT(G33,2) -> 30 | I33: =MID(G33,4,3) -> May | J33: 01 Jun 2026 | K33: =LEFT(J33,2) -> 01 | L33: =MID(J33,4,3) -> Jun | M33: 2 | N33: =+K33-H33 -> -29 | O33: =IF(I33=L33,0,31-H33) -> 1 | P33: =IF(I33=L33,0,K33-1) -> 0 | Q33: BOOKING | R33: ROOM | S33: 2 | T33: 1 | U33: 494.16108 | V33: 247.08054 | W33: Romania | X33: 15 Feb 2026 15:30 | Y33: 15 Feb 2026 | Z33: =MID(X33,4,3) -> Feb | AA33: =IF($I33=AA$1,IF($L33=AA$1,$M33,$O33),IF($L33=AA$1,$P33,0)) -> 1 | AB33: =IF($I33=AB$1,IF($L33=AB$1,$M33,$O33),IF($L33=AB$1,$P33,0)) -> 0 | AC33: =IF($I33=AC$1,IF($L33=AC$1,$M33,$O33),IF($L33=AC$1,$P33,0)) -> 0 | AD33: =IF($I33=AD$1,IF($L33=AD$1,$M33,$O33),IF($L33=AD$1,$P33,0)) -> 0 | AE33: =IF($I33=AE$1,IF($L33=AE$1,$M33,$O33),IF($L33=AE$1,$P33,0)) -> 0 | AF33: =SUM(AA33:AE33) -> 1 | AG33: =+AF33-M33 -> -1 | AH33: =LEFT(X33,2)&"."&VLOOKUP(MID(X33,4,3),'Data validation'!$A$1:$B$12,2,FALSE)&".2025" -> 15.02.2025 | AI33: =WEEKNUM(AH33) -> 7 | AJ33: =H33&"."&VLOOKUP(I33,'Data validation'!$A$1:$B$12,2,FALSE)&".2026" -> 30.05.2026 | AK33: =WEEKNUM(AJ33) -> 22 | AL33: =VLOOKUP(E33,[2]Sheet1!$A:$B,2,FALSE) -> #N/A
A34: =VLOOKUP(Q34,'Data validation'!$K$2:$L$50,2,FALSE) -> TO | B34: =AA34+IF(I34="Jun",IF(_xlfn.NUMBERVALUE(H34)>14,0,IF(_xlfn.NUMBERVALUE(K34)<14,M34,15-_xlfn.NUMBERVALUE(H34))),0) -> 0 | C34: =M34-B34-D34 -> 0 | D34: =IF(L34="Jul",IF(_xlfn.NUMBERVALUE(K34)<11,0,IF(I34="Jul",IF(_xlfn.NUMBERVALUE(H34)>11,M34,_xlfn.NUMBERVALUE(K34)-11),0)),0)+IF(L34="Aug",IF(_xlfn.NUMBERVALUE(K34)>24,IF(_xlfn.NUMBERVALUE(H34)>24,0,25-_xlfn.NUMBERVALUE(H34)),IF(I34="Aug",M34,_xlfn.NUMBERVALUE(K34)-1+32-_xlfn.NUMBERVALUE(H34))),0) -> 6 | E34: 10089 | F34: 1243618.234593 | G34: 14 Jul 2026 | H34: =LEFT(G34,2) -> 14 | I34: =MID(G34,4,3) -> Jul | J34: 20 Jul 2026 | K34: =LEFT(J34,2) -> 20 | L34: =MID(J34,4,3) -> Jul | M34: 6 | N34: =+K34-H34 -> 6 | O34: =IF(I34=L34,0,31-H34) -> 0 | P34: =IF(I34=L34,0,K34-1) -> 0 | Q34: СЛР-ХОЛИДЕЙ-СЪРВИС ЕООД | R34: ROOM-DELUXE | S34: 2 | T34: 1 | U34: =SUMIFS(SLR!L:L,SLR!D:D,'Резервации 2026'!E34) -> 2083.1936 | V34: =+U34/M34 -> 347.19894 | W34: Romania | X34: 15 Feb 2026 15:52 | Y34: 15 Feb 2026 | Z34: =MID(X34,4,3) -> Feb | AA34: =IF($I34=AA$1,IF($L34=AA$1,$M34,$O34),IF($L34=AA$1,$P34,0)) -> 0 | AB34: =IF($I34=AB$1,IF($L34=AB$1,$M34,$O34),IF($L34=AB$1,$P34,0)) -> 0 | AC34: =IF($I34=AC$1,IF($L34=AC$1,$M34,$O34),IF($L34=AC$1,$P34,0)) -> 6 | AD34: =IF($I34=AD$1,IF($L34=AD$1,$M34,$O34),IF($L34=AD$1,$P34,0)) -> 0 | AE34: =IF($I34=AE$1,IF($L34=AE$1,$M34,$O34),IF($L34=AE$1,$P34,0)) -> 0 | AF34: =SUM(AA34:AE34) -> 6 | AG34: =+AF34-M34 -> 0 | AH34: =LEFT(X34,2)&"."&VLOOKUP(MID(X34,4,3),'Data validation'!$A$1:$B$12,2,FALSE)&".2025" -> 15.02.2025 | AI34: =WEEKNUM(AH34) -> 7 | AJ34: =H34&"."&VLOOKUP(I34,'Data validation'!$A$1:$B$12,2,FALSE)&".2026" -> 14.07.2026 | AK34: =WEEKNUM(AJ34) -> 29 | AL34: =VLOOKUP(E34,[2]Sheet1!$A:$B,2,FALSE) -> #N/A
A35: =VLOOKUP(Q35,'Data validation'!$K$2:$L$50,2,FALSE) -> BOOKING | B35: =AA35+IF(I35="Jun",IF(_xlfn.NUMBERVALUE(H35)>14,0,IF(_xlfn.NUMBERVALUE(K35)<14,M35,15-_xlfn.NUMBERVALUE(H35))),0) -> 0 | C35: =M35-B35-D35 -> 4 | D35: =IF(L35="Jul",IF(_xlfn.NUMBERVALUE(K35)<11,0,IF(I35="Jul",IF(_xlfn.NUMBERVALUE(H35)>11,M35,_xlfn.NUMBERVALUE(K35)-11),0)),0)+IF(L35="Aug",IF(_xlfn.NUMBERVALUE(K35)>24,IF(_xlfn.NUMBERVALUE(H35)>24,0,25-_xlfn.NUMBERVALUE(H35)),IF(I35="Aug",M35,_xlfn.NUMBERVALUE(K35)-1+32-_xlfn.NUMBERVALUE(H35))),0) -> 0 | E35: 10038 | F35: 6956307117 | G35: 01 Jul 2026 | H35: =LEFT(G35,2) -> 01 | I35: =MID(G35,4,3) -> Jul | J35: 05 Jul 2026 | K35: =LEFT(J35,2) -> 05 | L35: =MID(J35,4,3) -> Jul | M35: 4 | N35: =+K35-H35 -> 4 | O35: =IF(I35=L35,0,31-H35) -> 0 | P35: =IF(I35=L35,0,K35-1) -> 0 | Q35: BOOKING | R35: ROOM | S35: 1 | T35: 2 | U35: 1720.8433 | V35: 430.21083 | W35: Bulgaria | X35: 09 Feb 2026 11:24 | Y35: 09 Feb 2026 | Z35: =MID(X35,4,3) -> Feb | AA35: =IF($I35=AA$1,IF($L35=AA$1,$M35,$O35),IF($L35=AA$1,$P35,0)) -> 0 | AB35: =IF($I35=AB$1,IF($L35=AB$1,$M35,$O35),IF($L35=AB$1,$P35,0)) -> 0 | AC35: =IF($I35=AC$1,IF($L35=AC$1,$M35,$O35),IF($L35=AC$1,$P35,0)) -> 4 | AD35: =IF($I35=AD$1,IF($L35=AD$1,$M35,$O35),IF($L35=AD$1,$P35,0)) -> 0 | AE35: =IF($I35=AE$1,IF($L35=AE$1,$M35,$O35),IF($L35=AE$1,$P35,0)) -> 0 | AF35: =SUM(AA35:AE35) -> 4 | AG35: =+AF35-M35 -> 0 | AH35: =LEFT(X35,2)&"."&VLOOKUP(MID(X35,4,3),'Data validation'!$A$1:$B$12,2,FALSE)&".2025" -> 09.02.2025 | AI35: =WEEKNUM(AH35) -> 7 | AJ35: =H35&"."&VLOOKUP(I35,'Data validation'!$A$1:$B$12,2,FALSE)&".2026" -> 01.07.2026 | AK35: =WEEKNUM(AJ35) -> 27 | AL35: =VLOOKUP(E35,[2]Sheet1!$A:$B,2,FALSE) -> Анулирана
